Workbook

Sheet HƯỚNG DẪN
A1: HỆ THỐNG QUẢN LÝ VẬN HÀNH XE TẢI - 2 CẤP
A2: Công ty TNHH Đầu tư Thương mại và Quảng cáo AN AN · 2 xe: 51D98246 (HINO), 51D69998 (ISUZU)
A4: MÀU Ô
A5: Xanh nhạt | B5: Admin nhập (cấp 1)
A6: Cam nhạt | B6: Quản lý nhập hoặc duyệt (cấp 2)
A7: Xám | B7: Công thức tự tính - không sửa
A9: CẤP 1 - ADMIN (tab xanh): nhập liệu và theo dõi hằng ngày
A10: LỆNH ĐIỀU XE | B10: Lập TRƯỚC khi xe chạy. 1 dòng = 1 chuyến: xe, tài xế, loại chuyến, công trình, km và giờ về dự kiến, khối lượng hàng, có tăng ca không.
A11: NHẬT KÝ NGÀY | B11: Sáng hôm sau: nhập 1 dòng cho mỗi xe từ 'Báo cáo tổng hợp' GPS Bình Minh, tick ảnh tài xế gửi và kiểm lốp. Xem cột 'Ngoại lệ cần xem' rồi nhắc tài xế ngay.
A12: CHẶNG TĂNG CA | B12: Chỉ nhập các chặng mở máy/tắt máy rơi vào trước 08h hoặc sau 17h. File tự cắt 4 khung giờ.
A13: NHẬT KÝ DẦU | B13: Mỗi lần đổ dầu: số lít, đơn giá, km đồng hồ, lít GPS ghi nhận, đủ 3 ảnh hay không.
A14: SỔ SỰ CỐ - CHI PHÍ | B14: Nổ lốp, hỏng xe, phạt nguội (tra thứ 2 hằng tuần), phí đường, bảo dưỡng, sửa chữa. Ghi rõ bên chịu và công trình.
A15: LỊCH XE - TÀI XẾ | B15: Cập nhật ngày hết hạn mỗi khi gia hạn. Báo quản lý khi có dòng vàng hoặc đỏ.
A17: CẤP 2 - QUẢN LÝ (tab cam): duyệt và ra quyết định
A18: Hằng ngày (2 phút) | B18: Không cần mở file. Admin chỉ báo khi có ngoại lệ nặng: không có lệnh, quá tải, sự cố.
A19: Thứ 7 hằng tuần | B19: Mở NHẬT KÝ NGÀY, lọc cột 'Đề xuất duyệt', chọn Quyết định OT ở cột cam. Sau đó xem BÁO CÁO TUẦN để chốt công và điểm tuân thủ từng tài xế.
A20: Đầu tháng | B20: Xem BÁO CÁO THÁNG: tỉ lệ lăn bánh, dầu so với định mức, chi phí/km, chi phí phân bổ theo công trình, lịch sắp đến hạn.
A21: THAM SỐ | B21: Chỉ quản lý sửa: định mức dầu, tải cho phép, đơn giá tăng ca, các ngưỡng cảnh báo, danh mục công trình.
A23: QUY TẮC VẬN HÀNH
A24: 1 | B24: Không có lệnh điều xe thì không duyệt tăng ca.
A25: 2 | B25: Tăng ca 'Đủ điều kiện' khi lệnh có ghi tăng ca VÀ chuyến đúng định mức (không trễ giờ về quá 30 phút, km không lệch quá 15%).
A26: 3 | B26: Khối lượng hàng trên lệnh không vượt tải cho phép của xe. Chuyến 'QUÁ TẢI' phải tách chuyến hoặc đổi xe.
A27: 4 | B27: Tài xế gửi ảnh ở 3 mốc: xuất phát, từng điểm giao, về xưởng; kiểm lốp trước khi chạy.
A28: 5 | B28: Mỗi chỉ số đỏ phải có một hành động: nhắc tài xế, trừ điểm tuân thủ, hoặc sửa cách điều xe.
A30: LƯU Ý
A31: Dữ liệu mẫu | B31: Các dòng ngày 05–09/10/2026 có ghi chú 'MẪU' là số minh họa để thấy cách file chạy. Xóa trước khi dùng thật (chỉ xóa ô xanh và cam, không xóa ô xám).
A32: Thêm xe, tài xế | B32: Thêm vào dòng trống ở THAM SỐ. Báo cáo tuần có sẵn 4 cột tài xế, báo cáo tháng có sẵn 3 cột xe.
A33: Thời lượng | B33: Cột TG lăn bánh, TG máy nổ nhập dạng giờ:phút (6:45). Giờ mở/tắt máy nhập dạng 06:38.
A34: Tải cho phép ISUZU | B34: Đang tạm ghi 1.900 kg - cần đối chiếu giấy đăng kiểm rồi sửa ở THAM SỐ.

Sheet LỆNH ĐIỀU XE
A1: LỆNH ĐIỀU XE
A2: CẤP 1 - Admin lập TRƯỚC khi xe lăn bánh, 1 dòng = 1 chuyến. Việc phát sinh trong ngày: thêm dòng, chọn 'Bổ sung trong ngày'.
A3: TỰ TÍNH | B3: ADMIN NHẬP | R3: TỰ TÍNH
A4: Mã lệnh | B4: Ngày | C4: Xe | D4: Tài xế | E4: Loại chuyến | F4: Công trình / Dự án | G4: Điểm đi | H4: Điểm đến / các điểm giao | I4: Số điểm giao | J4: Km dự kiến | K4: Giờ đi dự kiến | L4: Giờ về dự kiến | M4: Khối lượng hàng (kg) | N4: Có tăng ca kế hoạch | O4: Giờ tăng ca dự kiến | P4: Người lập | Q4: Thời điểm lập | R4: Tải cho phép (kg) | S4: % tải | T4: Cảnh báo tải | U4: Giờ về quy đổi | V4: Ghi chú
A5: =IF(B5="","","LDX-"&TEXT(B5,"yymmdd")&"-"&TEXT(COUNTIFS(B$5:B5,B5),"00")) -> LDX-261005-01 | B5: 46300 | C5: 51D98246 | D5: Nguyễn Chí Cang | E5: Trung chuyển kho | F5: Trung chuyển kho | G5: Xưởng Thới An | H5: Xưởng Cần Thơ | I5: 1 | J5: 175 | K5: 0.27083333 | L5: 0.77083333 | M5: 1500 | N5: Có | O5: 1.5 | P5: Admin | Q5: Trước chuyến | R5: =IF(C5="","",IFERROR(INDEX('THAM SỐ'!$F$5:$F$7,MATCH(C5,'THAM SỐ'!$A$5:$A$7,0)),"")) -> 1750 | S5: =IF(OR(M5="",R5="",R5=0),"",M5/R5) -> 0.85714286 | T5: =IF(S5="","",IF(S5>1,"QUÁ TẢI",IF(S5>0.9,"Sát tải","Đạt"))) -> Đạt | U5: =IF(L5="","",L5+(L5<4/24)) -> 0.77083333 | V5: MẪU
A6: =IF(B6="","","LDX-"&TEXT(B6,"yymmdd")&"-"&TEXT(COUNTIFS(B$5:B6,B6),"00")) -> LDX-261005-02 | B6: 46300 | C6: 51D69998 | D6: Khải | E6: Rải vật tư công trình | F6: Nippon Đức Tài | G6: Xưởng Thới An | H6: 611 Lạc Long Quân | I6: 2 | J6: 38 | K6: 0.33333333 | L6: 0.625 | M6: 900 | N6: Không | P6: Admin | Q6: Trước chuyến | R6: =IF(C6="","",IFERROR(INDEX('THAM SỐ'!$F$5:$F$7,MATCH(C6,'THAM SỐ'!$A$5:$A$7,0)),"")) -> 1900 | S6: =IF(OR(M6="",R6="",R6=0),"",M6/R6) -> 0.47368421 | T6: =IF(S6="","",IF(S6>1,"QUÁ TẢI",IF(S6>0.9,"Sát tải","Đạt"))) -> Đạt | U6: =IF(L6="","",L6+(L6<4/24)) -> 0.625 | V6: MẪU
A7: =IF(B7="","","LDX-"&TEXT(B7,"yymmdd")&"-"&TEXT(COUNTIFS(B$5:B7,B7),"00")) -> LDX-261006-01 | B7: 46301 | C7: 51D98246 | D7: Nguyễn Chí Cang | E7: Trung chuyển kho | F7: Trung chuyển kho | G7: Xưởng Cần Thơ | H7: Xưởng Thới An | I7: 1 | J7: 175 | K7: 0.33333333 | L7: 0.58333333 | M7: 1200 | N7: Không | P7: Admin | Q7: Trước chuyến | R7: =IF(C7="","",IFERROR(INDEX('THAM SỐ'!$F$5:$F$7,MATCH(C7,'THAM SỐ'!$A$5:$A$7,0)),"")) -> 1750 | S7: =IF(OR(M7="",R7="",R7=0),"",M7/R7) -> 0.68571429 | T7: =IF(S7="","",IF(S7>1,"QUÁ TẢI",IF(S7>0.9,"Sát tải","Đạt"))) -> Đạt | U7: =IF(L7="","",L7+(L7<4/24)) -> 0.58333333 | V7: MẪU
A8: =IF(B8="","","LDX-"&TEXT(B8,"yymmdd")&"-"&TEXT(COUNTIFS(B$5:B8,B8),"00")) -> LDX-261006-02 | B8: 46301 | C8: 51D69998 | D8: Khải | E8: Giao hàng dự án | F8: POSM CENTURY 2026 | G8: Xưởng Thới An | H8: 3 điểm Bình Dương | I8: 3 | J8: 85 | K8: 0.33333333 | L8: 0.70833333 | M8: 1600 | N8: Không | P8: Admin | Q8: Trước chuyến | R8: =IF(C8="","",IFERROR(INDEX('THAM SỐ'!$F$5:$F$7,MATCH(C8,'THAM SỐ'!$A$5:$A$7,0)),"")) -> 1900 | S8: =IF(OR(M8="",R8="",R8=0),"",M8/R8) -> 0.84210526 | T8: =IF(S8="","",IF(S8>1,"QUÁ TẢI",IF(S8>0.9,"Sát tải","Đạt"))) -> Đạt | U8: =IF(L8="","",L8+(L8<4/24)) -> 0.70833333 | V8: MẪU
A9: =IF(B9="","","LDX-"&TEXT(B9,"yymmdd")&"-"&TEXT(COUNTIFS(B$5:B9,B9),"00")) -> LDX-261007-01 | B9: 46302 | C9: 51D98246 | D9: Nguyễn Chí Cang | E9: Giao hàng dự án | F9: Galaxy | G9: Xưởng Thới An | H9: 2 rạp nội thành | I9: 2 | J9: 46 | K9: 0.33333333 | L9: 0.79166667 | M9: 1900 | N9: Có | O9: 2 | P9: Admin | Q9: Trước chuyến | R9: =IF(C9="","",IFERROR(INDEX('THAM SỐ'!$F$5:$F$7,MATCH(C9,'THAM SỐ'!$A$5:$A$7,0)),"")) -> 1750 | S9: =IF(OR(M9="",R9="",R9=0),"",M9/R9) -> 1.0857143 | T9: =IF(S9="","",IF(S9>1,"QUÁ TẢI",IF(S9>0.9,"Sát tải","Đạt"))) -> QUÁ TẢI | U9: =IF(L9="","",L9+(L9<4/24)) -> 0.79166667 | V9: MẪU
A10: =IF(B10="","","LDX-"&TEXT(B10,"yymmdd")&"-"&TEXT(COUNTIFS(B$5:B10,B10),"00")) -> LDX-261007-02 | B10: 46302 | C10: 51D69998 | D10: Khải | E10: Rải vật tư công trình | F10: Nippon Đức Tài | G10: Xưởng Thới An | H10: Hóc Môn, Bà Điểm | I10: 3 | J10: 42 | K10: 0.33333333 | L10: 0.66666667 | M10: 700 | N10: Không | P10: Admin | Q10: Bổ sung trong ngày | R10: =IF(C10="","",IFERROR(INDEX('THAM SỐ'!$F$5:$F$7,MATCH(C10,'THAM SỐ'!$A$5:$A$7,0)),"")) -> 1900 | S10: =IF(OR(M10="",R10="",R10=0),"",M10/R10) -> 0.36842105 | T10: =IF(S10="","",IF(S10>1,"QUÁ TẢI",IF(S10>0.9,"Sát tải","Đạt"))) -> Đạt | U10: =IF(L10="","",L10+(L10<4/24)) -> 0.66666667 | V10: MẪU
A11: =IF(B11="","","LDX-"&TEXT(B11,"yymmdd")&"-"&TEXT(COUNTIFS(B$5:B11,B11),"00")) -> LDX-261008-01 | B11: 46303 | C11: 51D98246 | D11: Nguyễn Chí Cang | E11: Rải vật tư công trình | F11: POSM CENTURY 2026 | G11: Xưởng Thới An | H11: Long An, Tiền Giang | I11: 4 | J11: 160 | K11: 0.29166667 | L11: 0.72916667 | M11: 1400 | N11: Có | O11: 1 | P11: Admin | Q11: Trước chuyến | R11: =IF(C11="","",IFERROR(INDEX('THAM SỐ'!$F$5:$F$7,MATCH(C11,'THAM SỐ'!$A$5:$A$7,0)),"")) -> 1750 | S11: =IF(OR(M11="",R11="",R11=0),"",M11/R11) -> 0.8 | T11: =IF(S11="","",IF(S11>1,"QUÁ TẢI",IF(S11>0.9,"Sát tải","Đạt"))) -> Đạt | U11: =IF(L11="","",L11+(L11<4/24)) -> 0.72916667 | V11: MẪU
A12: =IF(B12="","","LDX-"&TEXT(B12,"yymmdd")&"-"&TEXT(COUNTIFS(B$5:B12,B12),"00")) -> LDX-261008-02 | B12: 46303 | C12: 51D69998 | D12: Khải | E12: Giao hàng dự án | F12: Galaxy | G12: Xưởng Thới An | H12: Rạp Quận 7 | I12: 1 | J12: 52 | K12: 0.375 | L12: 0.58333333 | M12: 1100 | N12: Không | P12: Admin | Q12: Lập bù | R12: =IF(C12="","",IFERROR(INDEX('THAM SỐ'!$F$5:$F$7,MATCH(C12,'THAM SỐ'!$A$5:$A$7,0)),"")) -> 1900 | S12: =IF(OR(M12="",R12="",R12=0),"",M12/R12) -> 0.57894737 | T12: =IF(S12="","",IF(S12>1,"QUÁ TẢI",IF(S12>0.9,"Sát tải","Đạt"))) -> Đạt | U12: =IF(L12="","",L12+(L12<4/24)) -> 0.58333333 | V12: MẪU
A13: =IF(B13="","","LDX-"&TEXT(B13,"yymmdd")&"-"&TEXT(COUNTIFS(B$5:B13,B13),"00")) -> LDX-261009-01 | B13: 46304 | C13: 51D98246 | D13: Nguyễn Chí Cang | E13: Trung chuyển kho | F13: Trung chuyển kho | G13: Xưởng Thới An | H13: Xưởng Cần Thơ rồi quay về | I13: 1 | J13: 350 | K13: 0.22916667 | L13: 0.83333333 | M13: 1700 | N13: Có | O13: 3 | P13: Admin | Q13: Trước chuyến | R13: =IF(C13="","",IFERROR(INDEX('THAM SỐ'!$F$5:$F$7,MATCH(C13,'THAM SỐ'!$A$5:$A$7,0)),"")) -> 1750 | S13: =IF(OR(M13="",R13="",R13=0),"",M13/R13) -> 0.97142857 | T13: =IF(S13="","",IF(S13>1,"QUÁ TẢI",IF(S13>0.9,"Sát tải","Đạt"))) -> Sát tải | U13: =IF(L13="","",L13+(L13<4/24)) -> 0.83333333 | V13: MẪU
A14: =IF(B14="","","LDX-"&TEXT(B14,"yymmdd")&"-"&TEXT(COUNTIFS(B$5:B14,B14),"00")) | R14: =IF(C14="","",IFERROR(INDEX('THAM SỐ'!$F$5:$F$7,MATCH(C14,'THAM SỐ'!$A$5:$A$7,0)),"")) | S14: =IF(OR(M14="",R14="",R14=0),"",M14/R14) | T14: =IF(S14="","",IF(S14>1,"QUÁ TẢI",IF(S14>0.9,"Sát tải","Đạt"))) | U14: =IF(L14="","",L14+(L14<4/24))
A15: =IF(B15="","","LDX-"&TEXT(B15,"yymmdd")&"-"&TEXT(COUNTIFS(B$5:B15,B15),"00")) | R15: =IF(C15="","",IFERROR(INDEX('THAM SỐ'!$F$5:$F$7,MATCH(C15,'THAM SỐ'!$A$5:$A$7,0)),"")) | S15: =IF(OR(M15="",R15="",R15=0),"",M15/R15) | T15: =IF(S15="","",IF(S15>1,"QUÁ TẢI",IF(S15>0.9,"Sát tải","Đạt"))) | U15: =IF(L15="","",L15+(L15<4/24))
A16: =IF(B16="","","LDX-"&TEXT(B16,"yymmdd")&"-"&TEXT(COUNTIFS(B$5:B16,B16),"00")) | R16: =IF(C16="","",IFERROR(INDEX('THAM SỐ'!$F$5:$F$7,MATCH(C16,'THAM SỐ'!$A$5:$A$7,0)),"")) | S16: =IF(OR(M16="",R16="",R16=0),"",M16/R16) | T16: =IF(S16="","",IF(S16>1,"QUÁ TẢI",IF(S16>0.9,"Sát tải","Đạt"))) | U16: =IF(L16="","",L16+(L16<4/24))
A17: =IF(B17="","","LDX-"&TEXT(B17,"yymmdd")&"-"&TEXT(COUNTIFS(B$5:B17,B17),"00")) | R17: =IF(C17="","",IFERROR(INDEX('THAM SỐ'!$F$5:$F$7,MATCH(C17,'THAM SỐ'!$A$5:$A$7,0)),"")) | S17: =IF(OR(M17="",R17="",R17=0),"",M17/R17) | T17: =IF(S17="","",IF(S17>1,"QUÁ TẢI",IF(S17>0.9,"Sát tải","Đạt"))) | U17: =IF(L17="","",L17+(L17<4/24))
A18: =IF(B18="","","LDX-"&TEXT(B18,"yymmdd")&"-"&TEXT(COUNTIFS(B$5:B18,B18),"00")) | R18: =IF(C18="","",IFERROR(INDEX('THAM SỐ'!$F$5:$F$7,MATCH(C18,'THAM SỐ'!$A$5:$A$7,0)),"")) | S18: =IF(OR(M18="",R18="",R18=0),"",M18/R18) | T18: =IF(S18="","",IF(S18>1,"QUÁ TẢI",IF(S18>0.9,"Sát tải","Đạt"))) | U18: =IF(L18="","",L18+(L18<4/24))
A19: =IF(B19="","","LDX-"&TEXT(B19,"yymmdd")&"-"&TEXT(COUNTIFS(B$5:B19,B19),"00")) | R19: =IF(C19="","",IFERROR(INDEX('THAM SỐ'!$F$5:$F$7,MATCH(C19,'THAM SỐ'!$A$5:$A$7,0)),"")) | S19: =IF(OR(M19="",R19="",R19=0),"",M19/R19) | T19: =IF(S19="","",IF(S19>1,"QUÁ TẢI",IF(S19>0.9,"Sát tải","Đạt"))) | U19: =IF(L19="","",L19+(L19<4/24))
A20: =IF(B20="","","LDX-"&TEXT(B20,"yymmdd")&"-"&TEXT(COUNTIFS(B$5:B20,B20),"00")) | R20: =IF(C20="","",IFERROR(INDEX('THAM SỐ'!$F$5:$F$7,MATCH(C20,'THAM SỐ'!$A$5:$A$7,0)),"")) | S20: =IF(OR(M20="",R20="",R20=0),"",M20/R20) | T20: =IF(S20="","",IF(S20>1,"QUÁ TẢI",IF(S20>0.9,"Sát tải","Đạt"))) | U20: =IF(L20="","",L20+(L20<4/24))
A21: =IF(B21="","","LDX-"&TEXT(B21,"yymmdd")&"-"&TEXT(COUNTIFS(B$5:B21,B21),"00")) | R21: =IF(C21="","",IFERROR(INDEX('THAM SỐ'!$F$5:$F$7,MATCH(C21,'THAM SỐ'!$A$5:$A$7,0)),"")) | S21: =IF(OR(M21="",R21="",R21=0),"",M21/R21) | T21: =IF(S21="","",IF(S21>1,"QUÁ TẢI",IF(S21>0.9,"Sát tải","Đạt"))) | U21: =IF(L21="","",L21+(L21<4/24))
A22: =IF(B22="","","LDX-"&TEXT(B22,"yymmdd")&"-"&TEXT(COUNTIFS(B$5:B22,B22),"00")) | R22: =IF(C22="","",IFERROR(INDEX('THAM SỐ'!$F$5:$F$7,MATCH(C22,'THAM SỐ'!$A$5:$A$7,0)),"")) | S22: =IF(OR(M22="",R22="",R22=0),"",M22/R22) | T22: =IF(S22="","",IF(S22>1,"QUÁ TẢI",IF(S22>0.9,"Sát tải","Đạt"))) | U22: =IF(L22="","",L22+(L22<4/24))
A23: =IF(B23="","","LDX-"&TEXT(B23,"yymmdd")&"-"&TEXT(COUNTIFS(B$5:B23,B23),"00")) | R23: =IF(C23="","",IFERROR(INDEX('THAM SỐ'!$F$5:$F$7,MATCH(C23,'THAM SỐ'!$A$5:$A$7,0)),"")) | S23: =IF(OR(M23="",R23="",R23=0),"",M23/R23) | T23: =IF(S23="","",IF(S23>1,"QUÁ TẢI",IF(S23>0.9,"Sát tải","Đạt"))) | U23: =IF(L23="","",L23+(L23<4/24))
A24: =IF(B24="","","LDX-"&TEXT(B24,"yymmdd")&"-"&TEXT(COUNTIFS(B$5:B24,B24),"00")) | R24: =IF(C24="","",IFERROR(INDEX('THAM SỐ'!$F$5:$F$7,MATCH(C24,'THAM SỐ'!$A$5:$A$7,0)),"")) | S24: =IF(OR(M24="",R24="",R24=0),"",M24/R24) | T24: =IF(S24="","",IF(S24>1,"QUÁ TẢI",IF(S24>0.9,"Sát tải","Đạt"))) | U24: =IF(L24="","",L24+(L24<4/24))
A25: =IF(B25="","","LDX-"&TEXT(B25,"yymmdd")&"-"&TEXT(COUNTIFS(B$5:B25,B25),"00")) | R25: =IF(C25="","",IFERROR(INDEX('THAM SỐ'!$F$5:$F$7,MATCH(C25,'THAM SỐ'!$A$5:$A$7,0)),"")) | S25: =IF(OR(M25="",R25="",R25=0),"",M25/R25) | T25: =IF(S25="","",IF(S25>1,"QUÁ TẢI",IF(S25>0.9,"Sát tải","Đạt"))) | U25: =IF(L25="","",L25+(L25<4/24))
... A604: =IF(B604="","","LDX-"&TEXT(B604,"yymmdd")&"-"&TEXT(COUNTIFS(B$5:B604,B604),"00")) | R604: =IF(C604="","",IFERROR(INDEX('THAM SỐ'!$F$5:$F$7,MATCH(C604,'THAM SỐ'!$A$5:$A$7,0)),"")) | S604: =IF(OR(M604="",R604="",R604=0),"",M604/R604) | T604: =IF(S604="","",IF(S604>1,"QUÁ TẢI",IF(S604>0.9,"Sát tải","Đạt"))) | U604: =IF(L604="","",L604+(L604<4/24))

Sheet NHẬT KÝ NGÀY
A1: NHẬT KÝ NGÀY
A2: 1 dòng = 1 xe trong 1 ngày. CẤP 1 nhập cột xanh từ 'Báo cáo tổng hợp' GPS + ảnh Zalo của tài xế. CẤP 2 chỉ nhập cột cam (duyệt tăng ca). Thời lượng nhập dạng giờ:phút (vd 6:45).
A3: ADMIN NHẬP - TỪ GPS BÌNH MINH | N3: ĐỐI CHIẾU LỆNH | P3: TÀI XẾ BÁO CÁO | T3: TỰ TÍNH - VẬN HÀNH | AC3: TỰ TÍNH - TĂNG CA & NGOẠI LỆ | AM3: CẤP 2 DUYỆT
A4: Ngày | B4: Xe | C4: Tài xế | D4: Km GPS | E4: TG lăn bánh | F4: TG máy nổ | G4: Mở máy đầu | H4: Tắt máy cuối | I4: Số lần dừng đỗ | J4: Số lần quá tốc độ | K4: Số lần lái quá 4h | L4: Dừng >10p không tắt máy | M4: Nhiên liệu GPS (L) | N4: Dừng ngoài lệnh (lần) | O4: Dừng ngoài lệnh (phút) | P4: Ảnh xuất phát | Q4: Ảnh điểm giao | R4: Ảnh về xưởng | S4: Kiểm lốp đầu ngày | T4: Số lệnh | U4: Km dự kiến | V4: Lệch km | W4: Giờ có mặt | X4: Giờ lăn bánh | Y4: Giờ chờ | Z4: Tỉ lệ lăn bánh | AA4: Nổ máy đứng yên (giờ) | AB4: L/100km (GPS) | AC4: OT 04–08 | AD4: OT 17–22 | AE4: OT 22–24 | AF4: OT 24–04 | AG4: Tổng OT theo GPS | AH4: Có OT trong lệnh | AI4: Trễ giờ về (phút) | AJ4: Chuyến đúng định mức | AK4: Đề xuất duyệt | AL4: Ngoại lệ cần xem | AM4: Quyết định OT | AN4: Giờ duyệt (nếu một phần) | AO4: Giờ OT được duyệt | AP4: Tiền OT được duyệt | AQ4: Ghi chú
A5: 46300 | B5: 51D98246 | C5: Nguyễn Chí Cang | D5: 181 | E5: 0.18055556 | F5: 0.21527778 | G5: 0.26527778 | H5: 0.77777778 | I5: 6 | J5: 0 | K5: 0 | L5: 0 | M5: 20.5 | N5: 0 | O5: 0 | P5: Đủ | Q5: Đủ | R5: Đủ | S5: Đạt | T5: =IF($A5="","",COUNTIFS('LỆNH ĐIỀU XE'!$B$5:$B$604,$A5,'LỆNH ĐIỀU XE'!$C$5:$C$604,$B5)) -> 1 | U5: =IF($A5="","",SUMIFS('LỆNH ĐIỀU XE'!$J$5:$J$604,'LỆNH ĐIỀU XE'!$B$5:$B$604,$A5,'LỆNH ĐIỀU XE'!$C$5:$C$604,$B5)) -> 175 | V5: =IF(OR($A5="",D5="",N(U5)=0),"",(D5-U5)/U5) -> 0.034285714 | W5: =IF(OR($A5="",G5="",H5=""),"",ROUND((H5+(H5<G5)-G5)*24,2)) -> 12.3 | X5: =IF(OR($A5="",E5=""),"",ROUND(E5*24,2)) -> 4.33 | Y5: =IF(OR(W5="",X5=""),"",MAX(0,W5-X5)) -> 7.97 | Z5: =IF(OR(W5="",X5="",N(W5)=0),"",X5/W5) -> 0.35203252 | AA5: =IF(OR($A5="",F5="",X5=""),"",MAX(0,ROUND(F5*24-X5,2))) -> 0.84 | AB5: =IF(OR($A5="",M5="",N(D5)=0),"",M5/D5*100) -> 11.325967 | AC5: =IF($A5="","",SUMIFS('CHẶNG TĂNG CA'!$E$5:$E$304,'CHẶNG TĂNG CA'!$A$5:$A$304,$A5,'CHẶNG TĂNG CA'!$B$5:$B$304,$B5)) -> 1.63 | AD5: =IF($A5="","",SUMIFS('CHẶNG TĂNG CA'!$F$5:$F$304,'CHẶNG TĂNG CA'!$A$5:$A$304,$A5,'CHẶNG TĂNG CA'!$B$5:$B$304,$B5)) -> 1.67 | AE5: =IF($A5="","",SUMIFS('CHẶNG TĂNG CA'!$G$5:$G$304,'CHẶNG TĂNG CA'!$A$5:$A$304,$A5,'CHẶNG TĂNG CA'!$B$5:$B$304,$B5)) -> 0 | AF5: =IF($A5="","",SUMIFS('CHẶNG TĂNG CA'!$H$5:$H$304,'CHẶNG TĂNG CA'!$A$5:$A$304,$A5,'CHẶNG TĂNG CA'!$B$5:$B$304,$B5)) -> 0 | AG5: =IF($A5="","",SUM(AC5:AF5)) -> 3.3 | AH5: =IF($A5="","",IF(COUNTIFS('LỆNH ĐIỀU XE'!$B$5:$B$604,$A5,'LỆNH ĐIỀU XE'!$C$5:$C$604,$B5,'LỆNH ĐIỀU XE'!$N$5:$N$604,"Có")>0,"Có","Không")) -> Có | AI5: =IF(OR($A5="",H5="",N(T5)=0),"",IF(_xlfn.MAXIFS('LỆNH ĐIỀU XE'!$U$5:$U$604,'LỆNH ĐIỀU XE'!$B$5:$B$604,$A5,'LỆNH ĐIỀU XE'!$C$5:$C$604,$B5)=0,"",ROUND((H5+(H5<4/24)-_xlfn.MAXIFS('LỆNH ĐIỀU XE'!$U$5:$U$604,'LỆNH ĐIỀU XE'!$B$5:$B$604,$A5,'LỆNH ĐIỀU XE'!$C$5:$C$604,$B5))*1440,0))) -> 10 | AJ5: =IF($A5="","",IF(OR(AI5="",V5=""),"Thiếu dữ liệu",IF(AND(AI5<='THAM SỐ'!$B$29,ABS(V5)<='THAM SỐ'!$B$28),"Đạt","Không đạt"))) -> Đạt | AK5: =IF($A5="","",IF(AG5=0,"Không có OT",IF(AND(AH5="Có",AJ5="Đạt"),"Đủ điều kiện","Cần giải trình"))) -> Đủ điều kiện | AL5: =IF($A5="","",TRIM(IF(T5=0,"Không có lệnh; ","")&IF(N(N5)>0,"Dừng ngoài lệnh; ","")&IF(N(J5)>0,"Quá tốc độ; ","")&IF(N(K5)>0,"Lái quá 4h; ","")&IF(N(L5)>0,"Không tắt máy; ","")&IF(OR(P5<>"Đủ",Q5<>"Đủ",R5<>"Đủ"),"Thiếu ảnh; ","")&IF(S5<>"Đạt","Lốp chưa đạt; ","")&IF(N(W5)>'THAM SỐ'!$B$27,"Có mặt quá giờ; ","")&IF(N(X5)>'THAM SỐ'!$B$25,"Lái quá giờ ngày; ","")&IF(ISNUMBER(V5),IF(ABS(V5)>'THAM SỐ'!$B$28,"Lệch km; ",""),""))) -> Có mặt quá giờ; | AM5: Duyệt đủ | AO5: =IF($A5="","",IF(AM5="Duyệt đủ",AG5,IF(AM5="Duyệt một phần",N(AN5),IF(AM5="Không duyệt",0,"")))) -> 3.3 | AP5: =IF(OR($A5="",AO5=""),"",IF(AG5=0,0,ROUND((AC5*'THAM SỐ'!$B$18+AD5*'THAM SỐ'!$B$19+AE5*'THAM SỐ'!$B$20+AF5*'THAM SỐ'!$B$21)*MIN(1,AO5/AG5),0))) -> 205750 | AQ5: MẪU
A6: 46300 | B6: 51D69998 | C6: Khải | D6: 41 | E6: 0.086805556 | F6: 0.15277778 | G6: 0.33680556 | H6: 0.63888889 | I6: 5 | J6: 0 | K6: 0 | L6: 1 | M6: 5.8 | N6: 0 | O6: 0 | P6: Đủ | Q6: Đủ | R6: Thiếu | S6: Đạt | T6: =IF($A6="","",COUNTIFS('LỆNH ĐIỀU XE'!$B$5:$B$604,$A6,'LỆNH ĐIỀU XE'!$C$5:$C$604,$B6)) -> 1 | U6: =IF($A6="","",SUMIFS('LỆNH ĐIỀU XE'!$J$5:$J$604,'LỆNH ĐIỀU XE'!$B$5:$B$604,$A6,'LỆNH ĐIỀU XE'!$C$5:$C$604,$B6)) -> 38 | V6: =IF(OR($A6="",D6="",N(U6)=0),"",(D6-U6)/U6) -> 0.078947368 | W6: =IF(OR($A6="",G6="",H6=""),"",ROUND((H6+(H6<G6)-G6)*24,2)) -> 7.25 | X6: =IF(OR($A6="",E6=""),"",ROUND(E6*24,2)) -> 2.08 | Y6: =IF(OR(W6="",X6=""),"",MAX(0,W6-X6)) -> 5.17 | Z6: =IF(OR(W6="",X6="",N(W6)=0),"",X6/W6) -> 0.28689655 | AA6: =IF(OR($A6="",F6="",X6=""),"",MAX(0,ROUND(F6*24-X6,2))) -> 1.59 | AB6: =IF(OR($A6="",M6="",N(D6)=0),"",M6/D6*100) -> 14.146341 | AC6: =IF($A6="","",SUMIFS('CHẶNG TĂNG CA'!$E$5:$E$304,'CHẶNG TĂNG CA'!$A$5:$A$304,$A6,'CHẶNG TĂNG CA'!$B$5:$B$304,$B6)) -> 0 | AD6: =IF($A6="","",SUMIFS('CHẶNG TĂNG CA'!$F$5:$F$304,'CHẶNG TĂNG CA'!$A$5:$A$304,$A6,'CHẶNG TĂNG CA'!$B$5:$B$304,$B6)) -> 0 | AE6: =IF($A6="","",SUMIFS('CHẶNG TĂNG CA'!$G$5:$G$304,'CHẶNG TĂNG CA'!$A$5:$A$304,$A6,'CHẶNG TĂNG CA'!$B$5:$B$304,$B6)) -> 0 | AF6: =IF($A6="","",SUMIFS('CHẶNG TĂNG CA'!$H$5:$H$304,'CHẶNG TĂNG CA'!$A$5:$A$304,$A6,'CHẶNG TĂNG CA'!$B$5:$B$304,$B6)) -> 0 | AG6: =IF($A6="","",SUM(AC6:AF6)) -> 0 | AH6: =IF($A6="","",IF(COUNTIFS('LỆNH ĐIỀU XE'!$B$5:$B$604,$A6,'LỆNH ĐIỀU XE'!$C$5:$C$604,$B6,'LỆNH ĐIỀU XE'!$N$5:$N$604,"Có")>0,"Có","Không")) -> Không | AI6: =IF(OR($A6="",H6="",N(T6)=0),"",IF(_xlfn.MAXIFS('LỆNH ĐIỀU XE'!$U$5:$U$604,'LỆNH ĐIỀU XE'!$B$5:$B$604,$A6,'LỆNH ĐIỀU XE'!$C$5:$C$604,$B6)=0,"",ROUND((H6+(H6<4/24)-_xlfn.MAXIFS('LỆNH ĐIỀU XE'!$U$5:$U$604,'LỆNH ĐIỀU XE'!$B$5:$B$604,$A6,'LỆNH ĐIỀU XE'!$C$5:$C$604,$B6))*1440,0))) -> 20 | AJ6: =IF($A6="","",IF(OR(AI6="",V6=""),"Thiếu dữ liệu",IF(AND(AI6<='THAM SỐ'!$B$29,ABS(V6)<='THAM SỐ'!$B$28),"Đạt","Không đạt"))) -> Đạt | AK6: =IF($A6="","",IF(AG6=0,"Không có OT",IF(AND(AH6="Có",AJ6="Đạt"),"Đủ điều kiện","Cần giải trình"))) -> Không có OT | AL6: =IF($A6="","",TRIM(IF(T6=0,"Không có lệnh; ","")&IF(N(N6)>0,"Dừng ngoài lệnh; ","")&IF(N(J6)>0,"Quá tốc độ; ","")&IF(N(K6)>0,"Lái quá 4h; ","")&IF(N(L6)>0,"Không tắt máy; ","")&IF(OR(P6<>"Đủ",Q6<>"Đủ",R6<>"Đủ"),"Thiếu ảnh; ","")&IF(S6<>"Đạt","Lốp chưa đạt; ","")&IF(N(W6)>'THAM SỐ'!$B$27,"Có mặt quá giờ; ","")&IF(N(X6)>'THAM SỐ'!$B$25,"Lái quá giờ ngày; ","")&IF(ISNUMBER(V6),IF(ABS(V6)>'THAM SỐ'!$B$28,"Lệch km; ",""),""))) -> Không tắt máy; Thiếu ảnh; | AO6: =IF($A6="","",IF(AM6="Duyệt đủ",AG6,IF(AM6="Duyệt một phần",N(AN6),IF(AM6="Không duyệt",0,"")))) | AP6: =IF(OR($A6="",AO6=""),"",IF(AG6=0,0,ROUND((AC6*'THAM SỐ'!$B$18+AD6*'THAM SỐ'!$B$19+AE6*'THAM SỐ'!$B$20+AF6*'THAM SỐ'!$B$21)*MIN(1,AO6/AG6),0))) | AQ6: MẪU
A7: 46301 | B7: 51D98246 | C7: Nguyễn Chí Cang | D7: 178 | E7: 0.17708333 | F7: 0.20138889 | G7: 0.33472222 | H7: 0.59027778 | I7: 4 | J7: 1 | K7: 0 | L7: 0 | M7: 19.6 | N7: 0 | O7: 0 | P7: Đủ | Q7: Đủ | R7: Đủ | S7: Đạt | T7: =IF($A7="","",COUNTIFS('LỆNH ĐIỀU XE'!$B$5:$B$604,$A7,'LỆNH ĐIỀU XE'!$C$5:$C$604,$B7)) -> 1 | U7: =IF($A7="","",SUMIFS('LỆNH ĐIỀU XE'!$J$5:$J$604,'LỆNH ĐIỀU XE'!$B$5:$B$604,$A7,'LỆNH ĐIỀU XE'!$C$5:$C$604,$B7)) -> 175 | V7: =IF(OR($A7="",D7="",N(U7)=0),"",(D7-U7)/U7) -> 0.017142857 | W7: =IF(OR($A7="",G7="",H7=""),"",ROUND((H7+(H7<G7)-G7)*24,2)) -> 6.13 | X7: =IF(OR($A7="",E7=""),"",ROUND(E7*24,2)) -> 4.25 | Y7: =IF(OR(W7="",X7=""),"",MAX(0,W7-X7)) -> 1.88 | Z7: =IF(OR(W7="",X7="",N(W7)=0),"",X7/W7) -> 0.69331158 | AA7: =IF(OR($A7="",F7="",X7=""),"",MAX(0,ROUND(F7*24-X7,2))) -> 0.58 | AB7: =IF(OR($A7="",M7="",N(D7)=0),"",M7/D7*100) -> 11.011236 | AC7: =IF($A7="","",SUMIFS('CHẶNG TĂNG CA'!$E$5:$E$304,'CHẶNG TĂNG CA'!$A$5:$A$304,$A7,'CHẶNG TĂNG CA'!$B$5:$B$304,$B7)) -> 0 | AD7: =IF($A7="","",SUMIFS('CHẶNG TĂNG CA'!$F$5:$F$304,'CHẶNG TĂNG CA'!$A$5:$A$304,$A7,'CHẶNG TĂNG CA'!$B$5:$B$304,$B7)) -> 0 | AE7: =IF($A7="","",SUMIFS('CHẶNG TĂNG CA'!$G$5:$G$304,'CHẶNG TĂNG CA'!$A$5:$A$304,$A7,'CHẶNG TĂNG CA'!$B$5:$B$304,$B7)) -> 0 | AF7: =IF($A7="","",SUMIFS('CHẶNG TĂNG CA'!$H$5:$H$304,'CHẶNG TĂNG CA'!$A$5:$A$304,$A7,'CHẶNG TĂNG CA'!$B$5:$B$304,$B7)) -> 0 | AG7: =IF($A7="","",SUM(AC7:AF7)) -> 0 | AH7: =IF($A7="","",IF(COUNTIFS('LỆNH ĐIỀU XE'!$B$5:$B$604,$A7,'LỆNH ĐIỀU XE'!$C$5:$C$604,$B7,'LỆNH ĐIỀU XE'!$N$5:$N$604,"Có")>0,"Có","Không")) -> Không | AI7: =IF(OR($A7="",H7="",N(T7)=0),"",IF(_xlfn.MAXIFS('LỆNH ĐIỀU XE'!$U$5:$U$604,'LỆNH ĐIỀU XE'!$B$5:$B$604,$A7,'LỆNH ĐIỀU XE'!$C$5:$C$604,$B7)=0,"",ROUND((H7+(H7<4/24)-_xlfn.MAXIFS('LỆNH ĐIỀU XE'!$U$5:$U$604,'LỆNH ĐIỀU XE'!$B$5:$B$604,$A7,'LỆNH ĐIỀU XE'!$C$5:$C$604,$B7))*1440,0))) -> 10 | AJ7: =IF($A7="","",IF(OR(AI7="",V7=""),"Thiếu dữ liệu",IF(AND(AI7<='THAM SỐ'!$B$29,ABS(V7)<='THAM SỐ'!$B$28),"Đạt","Không đạt"))) -> Đạt | AK7: =IF($A7="","",IF(AG7=0,"Không có OT",IF(AND(AH7="Có",AJ7="Đạt"),"Đủ điều kiện","Cần giải trình"))) -> Không có OT | AL7: =IF($A7="","",TRIM(IF(T7=0,"Không có lệnh; ","")&IF(N(N7)>0,"Dừng ngoài lệnh; ","")&IF(N(J7)>0,"Quá tốc độ; ","")&IF(N(K7)>0,"Lái quá 4h; ","")&IF(N(L7)>0,"Không tắt máy; ","")&IF(OR(P7<>"Đủ",Q7<>"Đủ",R7<>"Đủ"),"Thiếu ảnh; ","")&IF(S7<>"Đạt","Lốp chưa đạt; ","")&IF(N(W7)>'THAM SỐ'!$B$27,"Có mặt quá giờ; ","")&IF(N(X7)>'THAM SỐ'!$B$25,"Lái quá giờ ngày; ","")&IF(ISNUMBER(V7),IF(ABS(V7)>'THAM SỐ'!$B$28,"Lệch km; ",""),""))) -> Quá tốc độ; | AO7: =IF($A7="","",IF(AM7="Duyệt đủ",AG7,IF(AM7="Duyệt một phần",N(AN7),IF(AM7="Không duyệt",0,"")))) | AP7: =IF(OR($A7="",AO7=""),"",IF(AG7=0,0,ROUND((AC7*'THAM SỐ'!$B$18+AD7*'THAM SỐ'!$B$19+AE7*'THAM SỐ'!$B$20+AF7*'THAM SỐ'!$B$21)*MIN(1,AO7/AG7),0))) | AQ7: MẪU
A8: 46301 | B8: 51D69998 | C8: Khải | D8: 97 | E8: 0.14583333 | F8: 0.23958333 | G8: 0.32986111 | H8: 0.73263889 | I8: 8 | J8: 0 | K8: 0 | L8: 2 | M8: 11.2 | N8: 1 | O8: 25 | P8: Đủ | Q8: Đủ | R8: Đủ | S8: Không làm | T8: =IF($A8="","",COUNTIFS('LỆNH ĐIỀU XE'!$B$5:$B$604,$A8,'LỆNH ĐIỀU XE'!$C$5:$C$604,$B8)) -> 1 | U8: =IF($A8="","",SUMIFS('LỆNH ĐIỀU XE'!$J$5:$J$604,'LỆNH ĐIỀU XE'!$B$5:$B$604,$A8,'LỆNH ĐIỀU XE'!$C$5:$C$604,$B8)) -> 85 | V8: =IF(OR($A8="",D8="",N(U8)=0),"",(D8-U8)/U8) -> 0.14117647 | W8: =IF(OR($A8="",G8="",H8=""),"",ROUND((H8+(H8<G8)-G8)*24,2)) -> 9.67 | X8: =IF(OR($A8="",E8=""),"",ROUND(E8*24,2)) -> 3.5 | Y8: =IF(OR(W8="",X8=""),"",MAX(0,W8-X8)) -> 6.17 | Z8: =IF(OR(W8="",X8="",N(W8)=0),"",X8/W8) -> 0.36194416 | AA8: =IF(OR($A8="",F8="",X8=""),"",MAX(0,ROUND(F8*24-X8,2))) -> 2.25 | AB8: =IF(OR($A8="",M8="",N(D8)=0),"",M8/D8*100) -> 11.546392 | AC8: =IF($A8="","",SUMIFS('CHẶNG TĂNG CA'!$E$5:$E$304,'CHẶNG TĂNG CA'!$A$5:$A$304,$A8,'CHẶNG TĂNG CA'!$B$5:$B$304,$B8)) -> 0.08 | AD8: =IF($A8="","",SUMIFS('CHẶNG TĂNG CA'!$F$5:$F$304,'CHẶNG TĂNG CA'!$A$5:$A$304,$A8,'CHẶNG TĂNG CA'!$B$5:$B$304,$B8)) -> 0.58 | AE8: =IF($A8="","",SUMIFS('CHẶNG TĂNG CA'!$G$5:$G$304,'CHẶNG TĂNG CA'!$A$5:$A$304,$A8,'CHẶNG TĂNG CA'!$B$5:$B$304,$B8)) -> 0 | AF8: =IF($A8="","",SUMIFS('CHẶNG TĂNG CA'!$H$5:$H$304,'CHẶNG TĂNG CA'!$A$5:$A$304,$A8,'CHẶNG TĂNG CA'!$B$5:$B$304,$B8)) -> 0 | AG8: =IF($A8="","",SUM(AC8:AF8)) -> 0.66 | AH8: =IF($A8="","",IF(COUNTIFS('LỆNH ĐIỀU XE'!$B$5:$B$604,$A8,'LỆNH ĐIỀU XE'!$C$5:$C$604,$B8,'LỆNH ĐIỀU XE'!$N$5:$N$604,"Có")>0,"Có","Không")) -> Không | AI8: =IF(OR($A8="",H8="",N(T8)=0),"",IF(_xlfn.MAXIFS('LỆNH ĐIỀU XE'!$U$5:$U$604,'LỆNH ĐIỀU XE'!$B$5:$B$604,$A8,'LỆNH ĐIỀU XE'!$C$5:$C$604,$B8)=0,"",ROUND((H8+(H8<4/24)-_xlfn.MAXIFS('LỆNH ĐIỀU XE'!$U$5:$U$604,'LỆNH ĐIỀU XE'!$B$5:$B$604,$A8,'LỆNH ĐIỀU XE'!$C$5:$C$604,$B8))*1440,0))) -> 35 | AJ8: =IF($A8="","",IF(OR(AI8="",V8=""),"Thiếu dữ liệu",IF(AND(AI8<='THAM SỐ'!$B$29,ABS(V8)<='THAM SỐ'!$B$28),"Đạt","Không đạt"))) -> Không đạt | AK8: =IF($A8="","",IF(AG8=0,"Không có OT",IF(AND(AH8="Có",AJ8="Đạt"),"Đủ điều kiện","Cần giải trình"))) -> Cần giải trình | AL8: =IF($A8="","",TRIM(IF(T8=0,"Không có lệnh; ","")&IF(N(N8)>0,"Dừng ngoài lệnh; ","")&IF(N(J8)>0,"Quá tốc độ; ","")&IF(N(K8)>0,"Lái quá 4h; ","")&IF(N(L8)>0,"Không tắt máy; ","")&IF(OR(P8<>"Đủ",Q8<>"Đủ",R8<>"Đủ"),"Thiếu ảnh; ","")&IF(S8<>"Đạt","Lốp chưa đạt; ","")&IF(N(W8)>'THAM SỐ'!$B$27,"Có mặt quá giờ; ","")&IF(N(X8)>'THAM SỐ'!$B$25,"Lái quá giờ ngày; ","")&IF(ISNUMBER(V8),IF(ABS(V8)>'THAM SỐ'!$B$28,"Lệch km; ",""),""))) -> Dừng ngoài lệnh; Không tắt máy; Lốp chưa đạt; | AO8: =IF($A8="","",IF(AM8="Duyệt đủ",AG8,IF(AM8="Duyệt một phần",N(AN8),IF(AM8="Không duyệt",0,"")))) | AP8: =IF(OR($A8="",AO8=""),"",IF(AG8=0,0,ROUND((AC8*'THAM SỐ'!$B$18+AD8*'THAM SỐ'!$B$19+AE8*'THAM SỐ'!$B$20+AF8*'THAM SỐ'!$B$21)*MIN(1,AO8/AG8),0))) | AQ8: MẪU
A9: 46302 | B9: 51D98246 | C9: Nguyễn Chí Cang | D9: 49 | E9: 0.090277778 | F9: 0.1875 | G9: 0.32638889 | H9: 0.80208333 | I9: 7 | J9: 0 | K9: 0 | L9: 1 | M9: 9.4 | N9: 0 | O9: 0 | P9: Đủ | Q9: Thiếu | R9: Đủ | S9: Đạt | T9: =IF($A9="","",COUNTIFS('LỆNH ĐIỀU XE'!$B$5:$B$604,$A9,'LỆNH ĐIỀU XE'!$C$5:$C$604,$B9)) -> 1 | U9: =IF($A9="","",SUMIFS('LỆNH ĐIỀU XE'!$J$5:$J$604,'LỆNH ĐIỀU XE'!$B$5:$B$604,$A9,'LỆNH ĐIỀU XE'!$C$5:$C$604,$B9)) -> 46 | V9: =IF(OR($A9="",D9="",N(U9)=0),"",(D9-U9)/U9) -> 0.065217391 | W9: =IF(OR($A9="",G9="",H9=""),"",ROUND((H9+(H9<G9)-G9)*24,2)) -> 11.42 | X9: =IF(OR($A9="",E9=""),"",ROUND(E9*24,2)) -> 2.17 | Y9: =IF(OR(W9="",X9=""),"",MAX(0,W9-X9)) -> 9.25 | Z9: =IF(OR(W9="",X9="",N(W9)=0),"",X9/W9) -> 0.19001751 | AA9: =IF(OR($A9="",F9="",X9=""),"",MAX(0,ROUND(F9*24-X9,2))) -> 2.33 | AB9: =IF(OR($A9="",M9="",N(D9)=0),"",M9/D9*100) -> 19.183673 | AC9: =IF($A9="","",SUMIFS('CHẶNG TĂNG CA'!$E$5:$E$304,'CHẶNG TĂNG CA'!$A$5:$A$304,$A9,'CHẶNG TĂNG CA'!$B$5:$B$304,$B9)) -> 0 | AD9: =IF($A9="","",SUMIFS('CHẶNG TĂNG CA'!$F$5:$F$304,'CHẶNG TĂNG CA'!$A$5:$A$304,$A9,'CHẶNG TĂNG CA'!$B$5:$B$304,$B9)) -> 2.25 | AE9: =IF($A9="","",SUMIFS('CHẶNG TĂNG CA'!$G$5:$G$304,'CHẶNG TĂNG CA'!$A$5:$A$304,$A9,'CHẶNG TĂNG CA'!$B$5:$B$304,$B9)) -> 0 | AF9: =IF($A9="","",SUMIFS('CHẶNG TĂNG CA'!$H$5:$H$304,'CHẶNG TĂNG CA'!$A$5:$A$304,$A9,'CHẶNG TĂNG CA'!$B$5:$B$304,$B9)) -> 0 | AG9: =IF($A9="","",SUM(AC9:AF9)) -> 2.25 | AH9: =IF($A9="","",IF(COUNTIFS('LỆNH ĐIỀU XE'!$B$5:$B$604,$A9,'LỆNH ĐIỀU XE'!$C$5:$C$604,$B9,'LỆNH ĐIỀU XE'!$N$5:$N$604,"Có")>0,"Có","Không")) -> Có | AI9: =IF(OR($A9="",H9="",N(T9)=0),"",IF(_xlfn.MAXIFS('LỆNH ĐIỀU XE'!$U$5:$U$604,'LỆNH ĐIỀU XE'!$B$5:$B$604,$A9,'LỆNH ĐIỀU XE'!$C$5:$C$604,$B9)=0,"",ROUND((H9+(H9<4/24)-_xlfn.MAXIFS('LỆNH ĐIỀU XE'!$U$5:$U$604,'LỆNH ĐIỀU XE'!$B$5:$B$604,$A9,'LỆNH ĐIỀU XE'!$C$5:$C$604,$B9))*1440,0))) -> 15 | AJ9: =IF($A9="","",IF(OR(AI9="",V9=""),"Thiếu dữ liệu",IF(AND(AI9<='THAM SỐ'!$B$29,ABS(V9)<='THAM SỐ'!$B$28),"Đạt","Không đạt"))) -> Đạt | AK9: =IF($A9="","",IF(AG9=0,"Không có OT",IF(AND(AH9="Có",AJ9="Đạt"),"Đủ điều kiện","Cần giải trình"))) -> Đủ điều kiện | AL9: =IF($A9="","",TRIM(IF(T9=0,"Không có lệnh; ","")&IF(N(N9)>0,"Dừng ngoài lệnh; ","")&IF(N(J9)>0,"Quá tốc độ; ","")&IF(N(K9)>0,"Lái quá 4h; ","")&IF(N(L9)>0,"Không tắt máy; ","")&IF(OR(P9<>"Đủ",Q9<>"Đủ",R9<>"Đủ"),"Thiếu ảnh; ","")&IF(S9<>"Đạt","Lốp chưa đạt; ","")&IF(N(W9)>'THAM SỐ'!$B$27,"Có mặt quá giờ; ","")&IF(N(X9)>'THAM SỐ'!$B$25,"Lái quá giờ ngày; ","")&IF(ISNUMBER(V9),IF(ABS(V9)>'THAM SỐ'!$B$28,"Lệch km; ",""),""))) -> Không tắt máy; Thiếu ảnh; | AM9: Duyệt một phần | AN9: 1 | AO9: =IF($A9="","",IF(AM9="Duyệt đủ",AG9,IF(AM9="Duyệt một phần",N(AN9),IF(AM9="Không duyệt",0,"")))) -> 1 | AP9: =IF(OR($A9="",AO9=""),"",IF(AG9=0,0,ROUND((AC9*'THAM SỐ'!$B$18+AD9*'THAM SỐ'!$B$19+AE9*'THAM SỐ'!$B$20+AF9*'THAM SỐ'!$B$21)*MIN(1,AO9/AG9),0))) -> 50000 | AQ9: MẪU
A10: 46302 | B10: 51D69998 | C10: Khải | D10: 44 | E10: 0.097222222 | F10: 0.11805556 | G10: 0.33333333 | H10: 0.65972222 | I10: 6 | J10: 0 | K10: 0 | L10: 0 | M10: 5.1 | N10: 0 | O10: 0 | P10: Đủ | Q10: Đủ | R10: Đủ | S10: Đạt | T10: =IF($A10="","",COUNTIFS('LỆNH ĐIỀU XE'!$B$5:$B$604,$A10,'LỆNH ĐIỀU XE'!$C$5:$C$604,$B10)) -> 1 | U10: =IF($A10="","",SUMIFS('LỆNH ĐIỀU XE'!$J$5:$J$604,'LỆNH ĐIỀU XE'!$B$5:$B$604,$A10,'LỆNH ĐIỀU XE'!$C$5:$C$604,$B10)) -> 42 | V10: =IF(OR($A10="",D10="",N(U10)=0),"",(D10-U10)/U10) -> 0.047619048 | W10: =IF(OR($A10="",G10="",H10=""),"",ROUND((H10+(H10<G10)-G10)*24,2)) -> 7.83 | X10: =IF(OR($A10="",E10=""),"",ROUND(E10*24,2)) -> 2.33 | Y10: =IF(OR(W10="",X10=""),"",MAX(0,W10-X10)) -> 5.5 | Z10: =IF(OR(W10="",X10="",N(W10)=0),"",X10/W10) -> 0.29757344 | AA10: =IF(OR($A10="",F10="",X10=""),"",MAX(0,ROUND(F10*24-X10,2))) -> 0.5 | AB10: =IF(OR($A10="",M10="",N(D10)=0),"",M10/D10*100) -> 11.590909 | AC10: =IF($A10="","",SUMIFS('CHẶNG TĂNG CA'!$E$5:$E$304,'CHẶNG TĂNG CA'!$A$5:$A$304,$A10,'CHẶNG TĂNG CA'!$B$5:$B$304,$B10)) -> 0 | AD10: =IF($A10="","",SUMIFS('CHẶNG TĂNG CA'!$F$5:$F$304,'CHẶNG TĂNG CA'!$A$5:$A$304,$A10,'CHẶNG TĂNG CA'!$B$5:$B$304,$B10)) -> 0 | AE10: =IF($A10="","",SUMIFS('CHẶNG TĂNG CA'!$G$5:$G$304,'CHẶNG TĂNG CA'!$A$5:$A$304,$A10,'CHẶNG TĂNG CA'!$B$5:$B$304,$B10)) -> 0 | AF10: =IF($A10="","",SUMIFS('CHẶNG TĂNG CA'!$H$5:$H$304,'CHẶNG TĂNG CA'!$A$5:$A$304,$A10,'CHẶNG TĂNG CA'!$B$5:$B$304,$B10)) -> 0 | AG10: =IF($A10="","",SUM(AC10:AF10)) -> 0 | AH10: =IF($A10="","",IF(COUNTIFS('LỆNH ĐIỀU XE'!$B$5:$B$604,$A10,'LỆNH ĐIỀU XE'!$C$5:$C$604,$B10,'LỆNH ĐIỀU XE'!$N$5:$N$604,"Có")>0,"Có","Không")) -> Không | AI10: =IF(OR($A10="",H10="",N(T10)=0),"",IF(_xlfn.MAXIFS('LỆNH ĐIỀU XE'!$U$5:$U$604,'LỆNH ĐIỀU XE'!$B$5:$B$604,$A10,'LỆNH ĐIỀU XE'!$C$5:$C$604,$B10)=0,"",ROUND((H10+(H10<4/24)-_xlfn.MAXIFS('LỆNH ĐIỀU XE'!$U$5:$U$604,'LỆNH ĐIỀU XE'!$B$5:$B$604,$A10,'LỆNH ĐIỀU XE'!$C$5:$C$604,$B10))*1440,0))) -> -10 | AJ10: =IF($A10="","",IF(OR(AI10="",V10=""),"Thiếu dữ liệu",IF(AND(AI10<='THAM SỐ'!$B$29,ABS(V10)<='THAM SỐ'!$B$28),"Đạt","Không đạt"))) -> Đạt | AK10: =IF($A10="","",IF(AG10=0,"Không có OT",IF(AND(AH10="Có",AJ10="Đạt"),"Đủ điều kiện","Cần giải trình"))) -> Không có OT | AL10: =IF($A10="","",TRIM(IF(T10=0,"Không có lệnh; ","")&IF(N(N10)>0,"Dừng ngoài lệnh; ","")&IF(N(J10)>0,"Quá tốc độ; ","")&IF(N(K10)>0,"Lái quá 4h; ","")&IF(N(L10)>0,"Không tắt máy; ","")&IF(OR(P10<>"Đủ",Q10<>"Đủ",R10<>"Đủ"),"Thiếu ảnh; ","")&IF(S10<>"Đạt","Lốp chưa đạt; ","")&IF(N(W10)>'THAM SỐ'!$B$27,"Có mặt quá giờ; ","")&IF(N(X10)>'THAM SỐ'!$B$25,"Lái quá giờ ngày; ","")&IF(ISNUMBER(V10),IF(ABS(V10)>'THAM SỐ'!$B$28,"Lệch km; ",""),""))) | AO10: =IF($A10="","",IF(AM10="Duyệt đủ",AG10,IF(AM10="Duyệt một phần",N(AN10),IF(AM10="Không duyệt",0,"")))) | AP10: =IF(OR($A10="",AO10=""),"",IF(AG10=0,0,ROUND((AC10*'THAM SỐ'!$B$18+AD10*'THAM SỐ'!$B$19+AE10*'THAM SỐ'!$B$20+AF10*'THAM SỐ'!$B$21)*MIN(1,AO10/AG10),0))) | AQ10: MẪU
A11: 46303 | B11: 51D98246 | C11: Nguyễn Chí Cang | D11: 166 | E11: 0.19444444 | F11: 0.22222222 | G11: 0.28472222 | H11: 0.75347222 | I11: 9 | J11: 0 | K11: 1 | L11: 0 | M11: 18.3 | N11: 0 | O11: 0 | P11: Đủ | Q11: Đủ | R11: Đủ | S11: Đạt | T11: =IF($A11="","",COUNTIFS('LỆNH ĐIỀU XE'!$B$5:$B$604,$A11,'LỆNH ĐIỀU XE'!$C$5:$C$604,$B11)) -> 1 | U11: =IF($A11="","",SUMIFS('LỆNH ĐIỀU XE'!$J$5:$J$604,'LỆNH ĐIỀU XE'!$B$5:$B$604,$A11,'LỆNH ĐIỀU XE'!$C$5:$C$604,$B11)) -> 160 | V11: =IF(OR($A11="",D11="",N(U11)=0),"",(D11-U11)/U11) -> 0.0375 | W11: =IF(OR($A11="",G11="",H11=""),"",ROUND((H11+(H11<G11)-G11)*24,2)) -> 11.25 | X11: =IF(OR($A11="",E11=""),"",ROUND(E11*24,2)) -> 4.67 | Y11: =IF(OR(W11="",X11=""),"",MAX(0,W11-X11)) -> 6.58 | Z11: =IF(OR(W11="",X11="",N(W11)=0),"",X11/W11) -> 0.41511111 | AA11: =IF(OR($A11="",F11="",X11=""),"",MAX(0,ROUND(F11*24-X11,2))) -> 0.66 | AB11: =IF(OR($A11="",M11="",N(D11)=0),"",M11/D11*100) -> 11.024096 | AC11: =IF($A11="","",SUMIFS('CHẶNG TĂNG CA'!$E$5:$E$304,'CHẶNG TĂNG CA'!$A$5:$A$304,$A11,'CHẶNG TĂNG CA'!$B$5:$B$304,$B11)) -> 1.17 | AD11: =IF($A11="","",SUMIFS('CHẶNG TĂNG CA'!$F$5:$F$304,'CHẶNG TĂNG CA'!$A$5:$A$304,$A11,'CHẶNG TĂNG CA'!$B$5:$B$304,$B11)) -> 1.08 | AE11: =IF($A11="","",SUMIFS('CHẶNG TĂNG CA'!$G$5:$G$304,'CHẶNG TĂNG CA'!$A$5:$A$304,$A11,'CHẶNG TĂNG CA'!$B$5:$B$304,$B11)) -> 0 | AF11: =IF($A11="","",SUMIFS('CHẶNG TĂNG CA'!$H$5:$H$304,'CHẶNG TĂNG CA'!$A$5:$A$304,$A11,'CHẶNG TĂNG CA'!$B$5:$B$304,$B11)) -> 0 | AG11: =IF($A11="","",SUM(AC11:AF11)) -> 2.25 | AH11: =IF($A11="","",IF(COUNTIFS('LỆNH ĐIỀU XE'!$B$5:$B$604,$A11,'LỆNH ĐIỀU XE'!$C$5:$C$604,$B11,'LỆNH ĐIỀU XE'!$N$5:$N$604,"Có")>0,"Có","Không")) -> Có | AI11: =IF(OR($A11="",H11="",N(T11)=0),"",IF(_xlfn.MAXIFS('LỆNH ĐIỀU XE'!$U$5:$U$604,'LỆNH ĐIỀU XE'!$B$5:$B$604,$A11,'LỆNH ĐIỀU XE'!$C$5:$C$604,$B11)=0,"",ROUND((H11+(H11<4/24)-_xlfn.MAXIFS('LỆNH ĐIỀU XE'!$U$5:$U$604,'LỆNH ĐIỀU XE'!$B$5:$B$604,$A11,'LỆNH ĐIỀU XE'!$C$5:$C$604,$B11))*1440,0))) -> 35 | AJ11: =IF($A11="","",IF(OR(AI11="",V11=""),"Thiếu dữ liệu",IF(AND(AI11<='THAM SỐ'!$B$29,ABS(V11)<='THAM SỐ'!$B$28),"Đạt","Không đạt"))) -> Không đạt | AK11: =IF($A11="","",IF(AG11=0,"Không có OT",IF(AND(AH11="Có",AJ11="Đạt"),"Đủ điều kiện","Cần giải trình"))) -> Cần giải trình | AL11: =IF($A11="","",TRIM(IF(T11=0,"Không có lệnh; ","")&IF(N(N11)>0,"Dừng ngoài lệnh; ","")&IF(N(J11)>0,"Quá tốc độ; ","")&IF(N(K11)>0,"Lái quá 4h; ","")&IF(N(L11)>0,"Không tắt máy; ","")&IF(OR(P11<>"Đủ",Q11<>"Đủ",R11<>"Đủ"),"Thiếu ảnh; ","")&IF(S11<>"Đạt","Lốp chưa đạt; ","")&IF(N(W11)>'THAM SỐ'!$B$27,"Có mặt quá giờ; ","")&IF(N(X11)>'THAM SỐ'!$B$25,"Lái quá giờ ngày; ","")&IF(ISNUMBER(V11),IF(ABS(V11)>'THAM SỐ'!$B$28,"Lệch km; ",""),""))) -> Lái quá 4h; | AO11: =IF($A11="","",IF(AM11="Duyệt đủ",AG11,IF(AM11="Duyệt một phần",N(AN11),IF(AM11="Không duyệt",0,"")))) | AP11: =IF(OR($A11="",AO11=""),"",IF(AG11=0,0,ROUND((AC11*'THAM SỐ'!$B$18+AD11*'THAM SỐ'!$B$19+AE11*'THAM SỐ'!$B$20+AF11*'THAM SỐ'!$B$21)*MIN(1,AO11/AG11),0))) | AQ11: MẪU
A12: 46303 | B12: 51D69998 | C12: Khải | D12: 55 | E12: 0.083333333 | F12: 0.10416667 | G12: 0.38194444 | H12: 0.58680556 | I12: 3 | J12: 0 | K12: 0 | L12: 0 | M12: 6.4 | N12: 0 | O12: 0 | P12: Đủ | Q12: Đủ | R12: Đủ | S12: Đạt | T12: =IF($A12="","",COUNTIFS('LỆNH ĐIỀU XE'!$B$5:$B$604,$A12,'LỆNH ĐIỀU XE'!$C$5:$C$604,$B12)) -> 1 | U12: =IF($A12="","",SUMIFS('LỆNH ĐIỀU XE'!$J$5:$J$604,'LỆNH ĐIỀU XE'!$B$5:$B$604,$A12,'LỆNH ĐIỀU XE'!$C$5:$C$604,$B12)) -> 52 | V12: =IF(OR($A12="",D12="",N(U12)=0),"",(D12-U12)/U12) -> 0.057692308 | W12: =IF(OR($A12="",G12="",H12=""),"",ROUND((H12+(H12<G12)-G12)*24,2)) -> 4.92 | X12: =IF(OR($A12="",E12=""),"",ROUND(E12*24,2)) -> 2 | Y12: =IF(OR(W12="",X12=""),"",MAX(0,W12-X12)) -> 2.92 | Z12: =IF(OR(W12="",X12="",N(W12)=0),"",X12/W12) -> 0.40650407 | AA12: =IF(OR($A12="",F12="",X12=""),"",MAX(0,ROUND(F12*24-X12,2))) -> 0.5 | AB12: =IF(OR($A12="",M12="",N(D12)=0),"",M12/D12*100) -> 11.636364 | AC12: =IF($A12="","",SUMIFS('CHẶNG TĂNG CA'!$E$5:$E$304,'CHẶNG TĂNG CA'!$A$5:$A$304,$A12,'CHẶNG TĂNG CA'!$B$5:$B$304,$B12)) -> 0 | AD12: =IF($A12="","",SUMIFS('CHẶNG TĂNG CA'!$F$5:$F$304,'CHẶNG TĂNG CA'!$A$5:$A$304,$A12,'CHẶNG TĂNG CA'!$B$5:$B$304,$B12)) -> 0 | AE12: =IF($A12="","",SUMIFS('CHẶNG TĂNG CA'!$G$5:$G$304,'CHẶNG TĂNG CA'!$A$5:$A$304,$A12,'CHẶNG TĂNG CA'!$B$5:$B$304,$B12)) -> 0 | AF12: =IF($A12="","",SUMIFS('CHẶNG TĂNG CA'!$H$5:$H$304,'CHẶNG TĂNG CA'!$A$5:$A$304,$A12,'CHẶNG TĂNG CA'!$B$5:$B$304,$B12)) -> 0 | AG12: =IF($A12="","",SUM(AC12:AF12)) -> 0 | AH12: =IF($A12="","",IF(COUNTIFS('LỆNH ĐIỀU XE'!$B$5:$B$604,$A12,'LỆNH ĐIỀU XE'!$C$5:$C$604,$B12,'LỆNH ĐIỀU XE'!$N$5:$N$604,"Có")>0,"Có","Không")) -> Không | AI12: =IF(OR($A12="",H12="",N(T12)=0),"",IF(_xlfn.MAXIFS('LỆNH ĐIỀU XE'!$U$5:$U$604,'LỆNH ĐIỀU XE'!$B$5:$B$604,$A12,'LỆNH ĐIỀU XE'!$C$5:$C$604,$B12)=0,"",ROUND((H12+(H12<4/24)-_xlfn.MAXIFS('LỆNH ĐIỀU XE'!$U$5:$U$604,'LỆNH ĐIỀU XE'!$B$5:$B$604,$A12,'LỆNH ĐIỀU XE'!$C$5:$C$604,$B12))*1440,0))) -> 5 | AJ12: =IF($A12="","",IF(OR(AI12="",V12=""),"Thiếu dữ liệu",IF(AND(AI12<='THAM SỐ'!$B$29,ABS(V12)<='THAM SỐ'!$B$28),"Đạt","Không đạt"))) -> Đạt | AK12: =IF($A12="","",IF(AG12=0,"Không có OT",IF(AND(AH12="Có",AJ12="Đạt"),"Đủ điều kiện","Cần giải trình"))) -> Không có OT | AL12: =IF($A12="","",TRIM(IF(T12=0,"Không có lệnh; ","")&IF(N(N12)>0,"Dừng ngoài lệnh; ","")&IF(N(J12)>0,"Quá tốc độ; ","")&IF(N(K12)>0,"Lái quá 4h; ","")&IF(N(L12)>0,"Không tắt máy; ","")&IF(OR(P12<>"Đủ",Q12<>"Đủ",R12<>"Đủ"),"Thiếu ảnh; ","")&IF(S12<>"Đạt","Lốp chưa đạt; ","")&IF(N(W12)>'THAM SỐ'!$B$27,"Có mặt quá giờ; ","")&IF(N(X12)>'THAM SỐ'!$B$25,"Lái quá giờ ngày; ","")&IF(ISNUMBER(V12),IF(ABS(V12)>'THAM SỐ'!$B$28,"Lệch km; ",""),""))) | AO12: =IF($A12="","",IF(AM12="Duyệt đủ",AG12,IF(AM12="Duyệt một phần",N(AN12),IF(AM12="Không duyệt",0,"")))) | AP12: =IF(OR($A12="",AO12=""),"",IF(AG12=0,0,ROUND((AC12*'THAM SỐ'!$B$18+AD12*'THAM SỐ'!$B$19+AE12*'THAM SỐ'!$B$20+AF12*'THAM SỐ'!$B$21)*MIN(1,AO12/AG12),0))) | AQ12: MẪU
A13: 46304 | B13: 51D98246 | C13: Nguyễn Chí Cang | D13: 356 | E13: 0.35416667 | F13: 0.38541667 | G13: 0.22569444 | H13: 0.84027778 | I13: 8 | J13: 2 | K13: 1 | L13: 0 | M13: 38.9 | N13: 0 | O13: 0 | P13: Đủ | Q13: Đủ | R13: Đủ | S13: Đạt | T13: =IF($A13="","",COUNTIFS('LỆNH ĐIỀU XE'!$B$5:$B$604,$A13,'LỆNH ĐIỀU XE'!$C$5:$C$604,$B13)) -> 1 | U13: =IF($A13="","",SUMIFS('LỆNH ĐIỀU XE'!$J$5:$J$604,'LỆNH ĐIỀU XE'!$B$5:$B$604,$A13,'LỆNH ĐIỀU XE'!$C$5:$C$604,$B13)) -> 350 | V13: =IF(OR($A13="",D13="",N(U13)=0),"",(D13-U13)/U13) -> 0.017142857 | W13: =IF(OR($A13="",G13="",H13=""),"",ROUND((H13+(H13<G13)-G13)*24,2)) -> 14.75 | X13: =IF(OR($A13="",E13=""),"",ROUND(E13*24,2)) -> 8.5 | Y13: =IF(OR(W13="",X13=""),"",MAX(0,W13-X13)) -> 6.25 | Z13: =IF(OR(W13="",X13="",N(W13)=0),"",X13/W13) -> 0.57627119 | AA13: =IF(OR($A13="",F13="",X13=""),"",MAX(0,ROUND(F13*24-X13,2))) -> 0.75 | AB13: =IF(OR($A13="",M13="",N(D13)=0),"",M13/D13*100) -> 10.926966 | AC13: =IF($A13="","",SUMIFS('CHẶNG TĂNG CA'!$E$5:$E$304,'CHẶNG TĂNG CA'!$A$5:$A$304,$A13,'CHẶNG TĂNG CA'!$B$5:$B$304,$B13)) -> 2.58 | AD13: =IF($A13="","",SUMIFS('CHẶNG TĂNG CA'!$F$5:$F$304,'CHẶNG TĂNG CA'!$A$5:$A$304,$A13,'CHẶNG TĂNG CA'!$B$5:$B$304,$B13)) -> 3.17 | AE13: =IF($A13="","",SUMIFS('CHẶNG TĂNG CA'!$G$5:$G$304,'CHẶNG TĂNG CA'!$A$5:$A$304,$A13,'CHẶNG TĂNG CA'!$B$5:$B$304,$B13)) -> 0 | AF13: =IF($A13="","",SUMIFS('CHẶNG TĂNG CA'!$H$5:$H$304,'CHẶNG TĂNG CA'!$A$5:$A$304,$A13,'CHẶNG TĂNG CA'!$B$5:$B$304,$B13)) -> 0 | AG13: =IF($A13="","",SUM(AC13:AF13)) -> 5.75 | AH13: =IF($A13="","",IF(COUNTIFS('LỆNH ĐIỀU XE'!$B$5:$B$604,$A13,'LỆNH ĐIỀU XE'!$C$5:$C$604,$B13,'LỆNH ĐIỀU XE'!$N$5:$N$604,"Có")>0,"Có","Không")) -> Có | AI13: =IF(OR($A13="",H13="",N(T13)=0),"",IF(_xlfn.MAXIFS('LỆNH ĐIỀU XE'!$U$5:$U$604,'LỆNH ĐIỀU XE'!$B$5:$B$604,$A13,'LỆNH ĐIỀU XE'!$C$5:$C$604,$B13)=0,"",ROUND((H13+(H13<4/24)-_xlfn.MAXIFS('LỆNH ĐIỀU XE'!$U$5:$U$604,'LỆNH ĐIỀU XE'!$B$5:$B$604,$A13,'LỆNH ĐIỀU XE'!$C$5:$C$604,$B13))*1440,0))) -> 10 | AJ13: =IF($A13="","",IF(OR(AI13="",V13=""),"Thiếu dữ liệu",IF(AND(AI13<='THAM SỐ'!$B$29,ABS(V13)<='THAM SỐ'!$B$28),"Đạt","Không đạt"))) -> Đạt | AK13: =IF($A13="","",IF(AG13=0,"Không có OT",IF(AND(AH13="Có",AJ13="Đạt"),"Đủ điều kiện","Cần giải trình"))) -> Đủ điều kiện | AL13: =IF($A13="","",TRIM(IF(T13=0,"Không có lệnh; ","")&IF(N(N13)>0,"Dừng ngoài lệnh; ","")&IF(N(J13)>0,"Quá tốc độ; ","")&IF(N(K13)>0,"Lái quá 4h; ","")&IF(N(L13)>0,"Không tắt máy; ","")&IF(OR(P13<>"Đủ",Q13<>"Đủ",R13<>"Đủ"),"Thiếu ảnh; ","")&IF(S13<>"Đạt","Lốp chưa đạt; ","")&IF(N(W13)>'THAM SỐ'!$B$27,"Có mặt quá giờ; ","")&IF(N(X13)>'THAM SỐ'!$B$25,"Lái quá giờ ngày; ","")&IF(ISNUMBER(V13),IF(ABS(V13)>'THAM SỐ'!$B$28,"Lệch km; ",""),""))) -> Quá tốc độ; Lái quá 4h; Có mặt quá giờ; | AO13: =IF($A13="","",IF(AM13="Duyệt đủ",AG13,IF(AM13="Duyệt một phần",N(AN13),IF(AM13="Không duyệt",0,"")))) | AP13: =IF(OR($A13="",AO13=""),"",IF(AG13=0,0,ROUND((AC13*'THAM SỐ'!$B$18+AD13*'THAM SỐ'!$B$19+AE13*'THAM SỐ'!$B$20+AF13*'THAM SỐ'!$B$21)*MIN(1,AO13/AG13),0))) | AQ13: MẪU
T14: =IF($A14="","",COUNTIFS('LỆNH ĐIỀU XE'!$B$5:$B$604,$A14,'LỆNH ĐIỀU XE'!$C$5:$C$604,$B14)) | U14: =IF($A14="","",SUMIFS('LỆNH ĐIỀU XE'!$J$5:$J$604,'LỆNH ĐIỀU XE'!$B$5:$B$604,$A14,'LỆNH ĐIỀU XE'!$C$5:$C$604,$B14)) | V14: =IF(OR($A14="",D14="",N(U14)=0),"",(D14-U14)/U14) | W14: =IF(OR($A14="",G14="",H14=""),"",ROUND((H14+(H14<G14)-G14)*24,2)) | X14: =IF(OR($A14="",E14=""),"",ROUND(E14*24,2)) | Y14: =IF(OR(W14="",X14=""),"",MAX(0,W14-X14)) | Z14: =IF(OR(W14="",X14="",N(W14)=0),"",X14/W14) | AA14: =IF(OR($A14="",F14="",X14=""),"",MAX(0,ROUND(F14*24-X14,2))) | AB14: =IF(OR($A14="",M14="",N(D14)=0),"",M14/D14*100) | AC14: =IF($A14="","",SUMIFS('CHẶNG TĂNG CA'!$E$5:$E$304,'CHẶNG TĂNG CA'!$A$5:$A$304,$A14,'CHẶNG TĂNG CA'!$B$5:$B$304,$B14)) | AD14: =IF($A14="","",SUMIFS('CHẶNG TĂNG CA'!$F$5:$F$304,'CHẶNG TĂNG CA'!$A$5:$A$304,$A14,'CHẶNG TĂNG CA'!$B$5:$B$304,$B14)) | AE14: =IF($A14="","",SUMIFS('CHẶNG TĂNG CA'!$G$5:$G$304,'CHẶNG TĂNG CA'!$A$5:$A$304,$A14,'CHẶNG TĂNG CA'!$B$5:$B$304,$B14)) | AF14: =IF($A14="","",SUMIFS('CHẶNG TĂNG CA'!$H$5:$H$304,'CHẶNG TĂNG CA'!$A$5:$A$304,$A14,'CHẶNG TĂNG CA'!$B$5:$B$304,$B14)) | AG14: =IF($A14="","",SUM(AC14:AF14)) | AH14: =IF($A14="","",IF(COUNTIFS('LỆNH ĐIỀU XE'!$B$5:$B$604,$A14,'LỆNH ĐIỀU XE'!$C$5:$C$604,$B14,'LỆNH ĐIỀU XE'!$N$5:$N$604,"Có")>0,"Có","Không")) | AI14: =IF(OR($A14="",H14="",N(T14)=0),"",IF(_xlfn.MAXIFS('LỆNH ĐIỀU XE'!$U$5:$U$604,'LỆNH ĐIỀU XE'!$B$5:$B$604,$A14,'LỆNH ĐIỀU XE'!$C$5:$C$604,$B14)=0,"",ROUND((H14+(H14<4/24)-_xlfn.MAXIFS('LỆNH ĐIỀU XE'!$U$5:$U$604,'LỆNH ĐIỀU XE'!$B$5:$B$604,$A14,'LỆNH ĐIỀU XE'!$C$5:$C$604,$B14))*1440,0))) | AJ14: =IF($A14="","",IF(OR(AI14="",V14=""),"Thiếu dữ liệu",IF(AND(AI14<='THAM SỐ'!$B$29,ABS(V14)<='THAM SỐ'!$B$28),"Đạt","Không đạt"))) | AK14: =IF($A14="","",IF(AG14=0,"Không có OT",IF(AND(AH14="Có",AJ14="Đạt"),"Đủ điều kiện","Cần giải trình"))) | AL14: =IF($A14="","",TRIM(IF(T14=0,"Không có lệnh; ","")&IF(N(N14)>0,"Dừng ngoài lệnh; ","")&IF(N(J14)>0,"Quá tốc độ; ","")&IF(N(K14)>0,"Lái quá 4h; ","")&IF(N(L14)>0,"Không tắt máy; ","")&IF(OR(P14<>"Đủ",Q14<>"Đủ",R14<>"Đủ"),"Thiếu ảnh; ","")&IF(S14<>"Đạt","Lốp chưa đạt; ","")&IF(N(W14)>'THAM SỐ'!$B$27,"Có mặt quá giờ; ","")&IF(N(X14)>'THAM SỐ'!$B$25,"Lái quá giờ ngày; ","")&IF(ISNUMBER(V14),IF(ABS(V14)>'THAM SỐ'!$B$28,"Lệch km; ",""),""))) | AO14: =IF($A14="","",IF(AM14="Duyệt đủ",AG14,IF(AM14="Duyệt một phần",N(AN14),IF(AM14="Không duyệt",0,"")))) | AP14: =IF(OR($A14="",AO14=""),"",IF(AG14=0,0,ROUND((AC14*'THAM SỐ'!$B$18+AD14*'THAM SỐ'!$B$19+AE14*'THAM SỐ'!$B$20+AF14*'THAM SỐ'!$B$21)*MIN(1,AO14/AG14),0)))
T15: =IF($A15="","",COUNTIFS('LỆNH ĐIỀU XE'!$B$5:$B$604,$A15,'LỆNH ĐIỀU XE'!$C$5:$C$604,$B15)) | U15: =IF($A15="","",SUMIFS('LỆNH ĐIỀU XE'!$J$5:$J$604,'LỆNH ĐIỀU XE'!$B$5:$B$604,$A15,'LỆNH ĐIỀU XE'!$C$5:$C$604,$B15)) | V15: =IF(OR($A15="",D15="",N(U15)=0),"",(D15-U15)/U15) | W15: =IF(OR($A15="",G15="",H15=""),"",ROUND((H15+(H15<G15)-G15)*24,2)) | X15: =IF(OR($A15="",E15=""),"",ROUND(E15*24,2)) | Y15: =IF(OR(W15="",X15=""),"",MAX(0,W15-X15)) | Z15: =IF(OR(W15="",X15="",N(W15)=0),"",X15/W15) | AA15: =IF(OR($A15="",F15="",X15=""),"",MAX(0,ROUND(F15*24-X15,2))) | AB15: =IF(OR($A15="",M15="",N(D15)=0),"",M15/D15*100) | AC15: =IF($A15="","",SUMIFS('CHẶNG TĂNG CA'!$E$5:$E$304,'CHẶNG TĂNG CA'!$A$5:$A$304,$A15,'CHẶNG TĂNG CA'!$B$5:$B$304,$B15)) | AD15: =IF($A15="","",SUMIFS('CHẶNG TĂNG CA'!$F$5:$F$304,'CHẶNG TĂNG CA'!$A$5:$A$304,$A15,'CHẶNG TĂNG CA'!$B$5:$B$304,$B15)) | AE15: =IF($A15="","",SUMIFS('CHẶNG TĂNG CA'!$G$5:$G$304,'CHẶNG TĂNG CA'!$A$5:$A$304,$A15,'CHẶNG TĂNG CA'!$B$5:$B$304,$B15)) | AF15: =IF($A15="","",SUMIFS('CHẶNG TĂNG CA'!$H$5:$H$304,'CHẶNG TĂNG CA'!$A$5:$A$304,$A15,'CHẶNG TĂNG CA'!$B$5:$B$304,$B15)) | AG15: =IF($A15="","",SUM(AC15:AF15)) | AH15: =IF($A15="","",IF(COUNTIFS('LỆNH ĐIỀU XE'!$B$5:$B$604,$A15,'LỆNH ĐIỀU XE'!$C$5:$C$604,$B15,'LỆNH ĐIỀU XE'!$N$5:$N$604,"Có")>0,"Có","Không")) | AI15: =IF(OR($A15="",H15="",N(T15)=0),"",IF(_xlfn.MAXIFS('LỆNH ĐIỀU XE'!$U$5:$U$604,'LỆNH ĐIỀU XE'!$B$5:$B$604,$A15,'LỆNH ĐIỀU XE'!$C$5:$C$604,$B15)=0,"",ROUND((H15+(H15<4/24)-_xlfn.MAXIFS('LỆNH ĐIỀU XE'!$U$5:$U$604,'LỆNH ĐIỀU XE'!$B$5:$B$604,$A15,'LỆNH ĐIỀU XE'!$C$5:$C$604,$B15))*1440,0))) | AJ15: =IF($A15="","",IF(OR(AI15="",V15=""),"Thiếu dữ liệu",IF(AND(AI15<='THAM SỐ'!$B$29,ABS(V15)<='THAM SỐ'!$B$28),"Đạt","Không đạt"))) | AK15: =IF($A15="","",IF(AG15=0,"Không có OT",IF(AND(AH15="Có",AJ15="Đạt"),"Đủ điều kiện","Cần giải trình"))) | AL15: =IF($A15="","",TRIM(IF(T15=0,"Không có lệnh; ","")&IF(N(N15)>0,"Dừng ngoài lệnh; ","")&IF(N(J15)>0,"Quá tốc độ; ","")&IF(N(K15)>0,"Lái quá 4h; ","")&IF(N(L15)>0,"Không tắt máy; ","")&IF(OR(P15<>"Đủ",Q15<>"Đủ",R15<>"Đủ"),"Thiếu ảnh; ","")&IF(S15<>"Đạt","Lốp chưa đạt; ","")&IF(N(W15)>'THAM SỐ'!$B$27,"Có mặt quá giờ; ","")&IF(N(X15)>'THAM SỐ'!$B$25,"Lái quá giờ ngày; ","")&IF(ISNUMBER(V15),IF(ABS(V15)>'THAM SỐ'!$B$28,"Lệch km; ",""),""))) | AO15: =IF($A15="","",IF(AM15="Duyệt đủ",AG15,IF(AM15="Duyệt một phần",N(AN15),IF(AM15="Không duyệt",0,"")))) | AP15: =IF(OR($A15="",AO15=""),"",IF(AG15=0,0,ROUND((AC15*'THAM SỐ'!$B$18+AD15*'THAM SỐ'!$B$19+AE15*'THAM SỐ'!$B$20+AF15*'THAM SỐ'!$B$21)*MIN(1,AO15/AG15),0)))
T16: =IF($A16="","",COUNTIFS('LỆNH ĐIỀU XE'!$B$5:$B$604,$A16,'LỆNH ĐIỀU XE'!$C$5:$C$604,$B16)) | U16: =IF($A16="","",SUMIFS('LỆNH ĐIỀU XE'!$J$5:$J$604,'LỆNH ĐIỀU XE'!$B$5:$B$604,$A16,'LỆNH ĐIỀU XE'!$C$5:$C$604,$B16)) | V16: =IF(OR($A16="",D16="",N(U16)=0),"",(D16-U16)/U16) | W16: =IF(OR($A16="",G16="",H16=""),"",ROUND((H16+(H16<G16)-G16)*24,2)) | X16: =IF(OR($A16="",E16=""),"",ROUND(E16*24,2)) | Y16: =IF(OR(W16="",X16=""),"",MAX(0,W16-X16)) | Z16: =IF(OR(W16="",X16="",N(W16)=0),"",X16/W16) | AA16: =IF(OR($A16="",F16="",X16=""),"",MAX(0,ROUND(F16*24-X16,2))) | AB16: =IF(OR($A16="",M16="",N(D16)=0),"",M16/D16*100) | AC16: =IF($A16="","",SUMIFS('CHẶNG TĂNG CA'!$E$5:$E$304,'CHẶNG TĂNG CA'!$A$5:$A$304,$A16,'CHẶNG TĂNG CA'!$B$5:$B$304,$B16)) | AD16: =IF($A16="","",SUMIFS('CHẶNG TĂNG CA'!$F$5:$F$304,'CHẶNG TĂNG CA'!$A$5:$A$304,$A16,'CHẶNG TĂNG CA'!$B$5:$B$304,$B16)) | AE16: =IF($A16="","",SUMIFS('CHẶNG TĂNG CA'!$G$5:$G$304,'CHẶNG TĂNG CA'!$A$5:$A$304,$A16,'CHẶNG TĂNG CA'!$B$5:$B$304,$B16)) | AF16: =IF($A16="","",SUMIFS('CHẶNG TĂNG CA'!$H$5:$H$304,'CHẶNG TĂNG CA'!$A$5:$A$304,$A16,'CHẶNG TĂNG CA'!$B$5:$B$304,$B16)) | AG16: =IF($A16="","",SUM(AC16:AF16)) | AH16: =IF($A16="","",IF(COUNTIFS('LỆNH ĐIỀU XE'!$B$5:$B$604,$A16,'LỆNH ĐIỀU XE'!$C$5:$C$604,$B16,'LỆNH ĐIỀU XE'!$N$5:$N$604,"Có")>0,"Có","Không")) | AI16: =IF(OR($A16="",H16="",N(T16)=0),"",IF(_xlfn.MAXIFS('LỆNH ĐIỀU XE'!$U$5:$U$604,'LỆNH ĐIỀU XE'!$B$5:$B$604,$A16,'LỆNH ĐIỀU XE'!$C$5:$C$604,$B16)=0,"",ROUND((H16+(H16<4/24)-_xlfn.MAXIFS('LỆNH ĐIỀU XE'!$U$5:$U$604,'LỆNH ĐIỀU XE'!$B$5:$B$604,$A16,'LỆNH ĐIỀU XE'!$C$5:$C$604,$B16))*1440,0))) | AJ16: =IF($A16="","",IF(OR(AI16="",V16=""),"Thiếu dữ liệu",IF(AND(AI16<='THAM SỐ'!$B$29,ABS(V16)<='THAM SỐ'!$B$28),"Đạt","Không đạt"))) | AK16: =IF($A16="","",IF(AG16=0,"Không có OT",IF(AND(AH16="Có",AJ16="Đạt"),"Đủ điều kiện","Cần giải trình"))) | AL16: =IF($A16="","",TRIM(IF(T16=0,"Không có lệnh; ","")&IF(N(N16)>0,"Dừng ngoài lệnh; ","")&IF(N(J16)>0,"Quá tốc độ; ","")&IF(N(K16)>0,"Lái quá 4h; ","")&IF(N(L16)>0,"Không tắt máy; ","")&IF(OR(P16<>"Đủ",Q16<>"Đủ",R16<>"Đủ"),"Thiếu ảnh; ","")&IF(S16<>"Đạt","Lốp chưa đạt; ","")&IF(N(W16)>'THAM SỐ'!$B$27,"Có mặt quá giờ; ","")&IF(N(X16)>'THAM SỐ'!$B$25,"Lái quá giờ ngày; ","")&IF(ISNUMBER(V16),IF(ABS(V16)>'THAM SỐ'!$B$28,"Lệch km; ",""),""))) | AO16: =IF($A16="","",IF(AM16="Duyệt đủ",AG16,IF(AM16="Duyệt một phần",N(AN16),IF(AM16="Không duyệt",0,"")))) | AP16: =IF(OR($A16="",AO16=""),"",IF(AG16=0,0,ROUND((AC16*'THAM SỐ'!$B$18+AD16*'THAM SỐ'!$B$19+AE16*'THAM SỐ'!$B$20+AF16*'THAM SỐ'!$B$21)*MIN(1,AO16/AG16),0)))
T17: =IF($A17="","",COUNTIFS('LỆNH ĐIỀU XE'!$B$5:$B$604,$A17,'LỆNH ĐIỀU XE'!$C$5:$C$604,$B17)) | U17: =IF($A17="","",SUMIFS('LỆNH ĐIỀU XE'!$J$5:$J$604,'LỆNH ĐIỀU XE'!$B$5:$B$604,$A17,'LỆNH ĐIỀU XE'!$C$5:$C$604,$B17)) | V17: =IF(OR($A17="",D17="",N(U17)=0),"",(D17-U17)/U17) | W17: =IF(OR($A17="",G17="",H17=""),"",ROUND((H17+(H17<G17)-G17)*24,2)) | X17: =IF(OR($A17="",E17=""),"",ROUND(E17*24,2)) | Y17: =IF(OR(W17="",X17=""),"",MAX(0,W17-X17)) | Z17: =IF(OR(W17="",X17="",N(W17)=0),"",X17/W17) | AA17: =IF(OR($A17="",F17="",X17=""),"",MAX(0,ROUND(F17*24-X17,2))) | AB17: =IF(OR($A17="",M17="",N(D17)=0),"",M17/D17*100) | AC17: =IF($A17="","",SUMIFS('CHẶNG TĂNG CA'!$E$5:$E$304,'CHẶNG TĂNG CA'!$A$5:$A$304,$A17,'CHẶNG TĂNG CA'!$B$5:$B$304,$B17)) | AD17: =IF($A17="","",SUMIFS('CHẶNG TĂNG CA'!$F$5:$F$304,'CHẶNG TĂNG CA'!$A$5:$A$304,$A17,'CHẶNG TĂNG CA'!$B$5:$B$304,$B17)) | AE17: =IF($A17="","",SUMIFS('CHẶNG TĂNG CA'!$G$5:$G$304,'CHẶNG TĂNG CA'!$A$5:$A$304,$A17,'CHẶNG TĂNG CA'!$B$5:$B$304,$B17)) | AF17: =IF($A17="","",SUMIFS('CHẶNG TĂNG CA'!$H$5:$H$304,'CHẶNG TĂNG CA'!$A$5:$A$304,$A17,'CHẶNG TĂNG CA'!$B$5:$B$304,$B17)) | AG17: =IF($A17="","",SUM(AC17:AF17)) | AH17: =IF($A17="","",IF(COUNTIFS('LỆNH ĐIỀU XE'!$B$5:$B$604,$A17,'LỆNH ĐIỀU XE'!$C$5:$C$604,$B17,'LỆNH ĐIỀU XE'!$N$5:$N$604,"Có")>0,"Có","Không")) | AI17: =IF(OR($A17="",H17="",N(T17)=0),"",IF(_xlfn.MAXIFS('LỆNH ĐIỀU XE'!$U$5:$U$604,'LỆNH ĐIỀU XE'!$B$5:$B$604,$A17,'LỆNH ĐIỀU XE'!$C$5:$C$604,$B17)=0,"",ROUND((H17+(H17<4/24)-_xlfn.MAXIFS('LỆNH ĐIỀU XE'!$U$5:$U$604,'LỆNH ĐIỀU XE'!$B$5:$B$604,$A17,'LỆNH ĐIỀU XE'!$C$5:$C$604,$B17))*1440,0))) | AJ17: =IF($A17="","",IF(OR(AI17="",V17=""),"Thiếu dữ liệu",IF(AND(AI17<='THAM SỐ'!$B$29,ABS(V17)<='THAM SỐ'!$B$28),"Đạt","Không đạt"))) | AK17: =IF($A17="","",IF(AG17=0,"Không có OT",IF(AND(AH17="Có",AJ17="Đạt"),"Đủ điều kiện","Cần giải trình"))) | AL17: =IF($A17="","",TRIM(IF(T17=0,"Không có lệnh; ","")&IF(N(N17)>0,"Dừng ngoài lệnh; ","")&IF(N(J17)>0,"Quá tốc độ; ","")&IF(N(K17)>0,"Lái quá 4h; ","")&IF(N(L17)>0,"Không tắt máy; ","")&IF(OR(P17<>"Đủ",Q17<>"Đủ",R17<>"Đủ"),"Thiếu ảnh; ","")&IF(S17<>"Đạt","Lốp chưa đạt; ","")&IF(N(W17)>'THAM SỐ'!$B$27,"Có mặt quá giờ; ","")&IF(N(X17)>'THAM SỐ'!$B$25,"Lái quá giờ ngày; ","")&IF(ISNUMBER(V17),IF(ABS(V17)>'THAM SỐ'!$B$28,"Lệch km; ",""),""))) | AO17: =IF($A17="","",IF(AM17="Duyệt đủ",AG17,IF(AM17="Duyệt một phần",N(AN17),IF(AM17="Không duyệt",0,"")))) | AP17: =IF(OR($A17="",AO17=""),"",IF(AG17=0,0,ROUND((AC17*'THAM SỐ'!$B$18+AD17*'THAM SỐ'!$B$19+AE17*'THAM SỐ'!$B$20+AF17*'THAM SỐ'!$B$21)*MIN(1,AO17/AG17),0)))
T18: =IF($A18="","",COUNTIFS('LỆNH ĐIỀU XE'!$B$5:$B$604,$A18,'LỆNH ĐIỀU XE'!$C$5:$C$604,$B18)) | U18: =IF($A18="","",SUMIFS('LỆNH ĐIỀU XE'!$J$5:$J$604,'LỆNH ĐIỀU XE'!$B$5:$B$604,$A18,'LỆNH ĐIỀU XE'!$C$5:$C$604,$B18)) | V18: =IF(OR($A18="",D18="",N(U18)=0),"",(D18-U18)/U18) | W18: =IF(OR($A18="",G18="",H18=""),"",ROUND((H18+(H18<G18)-G18)*24,2)) | X18: =IF(OR($A18="",E18=""),"",ROUND(E18*24,2)) | Y18: =IF(OR(W18="",X18=""),"",MAX(0,W18-X18)) | Z18: =IF(OR(W18="",X18="",N(W18)=0),"",X18/W18) | AA18: =IF(OR($A18="",F18="",X18=""),"",MAX(0,ROUND(F18*24-X18,2))) | AB18: =IF(OR($A18="",M18="",N(D18)=0),"",M18/D18*100) | AC18: =IF($A18="","",SUMIFS('CHẶNG TĂNG CA'!$E$5:$E$304,'CHẶNG TĂNG CA'!$A$5:$A$304,$A18,'CHẶNG TĂNG CA'!$B$5:$B$304,$B18)) | AD18: =IF($A18="","",SUMIFS('CHẶNG TĂNG CA'!$F$5:$F$304,'CHẶNG TĂNG CA'!$A$5:$A$304,$A18,'CHẶNG TĂNG CA'!$B$5:$B$304,$B18)) | AE18: =IF($A18="","",SUMIFS('CHẶNG TĂNG CA'!$G$5:$G$304,'CHẶNG TĂNG CA'!$A$5:$A$304,$A18,'CHẶNG TĂNG CA'!$B$5:$B$304,$B18)) | AF18: =IF($A18="","",SUMIFS('CHẶNG TĂNG CA'!$H$5:$H$304,'CHẶNG TĂNG CA'!$A$5:$A$304,$A18,'CHẶNG TĂNG CA'!$B$5:$B$304,$B18)) | AG18: =IF($A18="","",SUM(AC18:AF18)) | AH18: =IF($A18="","",IF(COUNTIFS('LỆNH ĐIỀU XE'!$B$5:$B$604,$A18,'LỆNH ĐIỀU XE'!$C$5:$C$604,$B18,'LỆNH ĐIỀU XE'!$N$5:$N$604,"Có")>0,"Có","Không")) | AI18: =IF(OR($A18="",H18="",N(T18)=0),"",IF(_xlfn.MAXIFS('LỆNH ĐIỀU XE'!$U$5:$U$604,'LỆNH ĐIỀU XE'!$B$5:$B$604,$A18,'LỆNH ĐIỀU XE'!$C$5:$C$604,$B18)=0,"",ROUND((H18+(H18<4/24)-_xlfn.MAXIFS('LỆNH ĐIỀU XE'!$U$5:$U$604,'LỆNH ĐIỀU XE'!$B$5:$B$604,$A18,'LỆNH ĐIỀU XE'!$C$5:$C$604,$B18))*1440,0))) | AJ18: =IF($A18="","",IF(OR(AI18="",V18=""),"Thiếu dữ liệu",IF(AND(AI18<='THAM SỐ'!$B$29,ABS(V18)<='THAM SỐ'!$B$28),"Đạt","Không đạt"))) | AK18: =IF($A18="","",IF(AG18=0,"Không có OT",IF(AND(AH18="Có",AJ18="Đạt"),"Đủ điều kiện","Cần giải trình"))) | AL18: =IF($A18="","",TRIM(IF(T18=0,"Không có lệnh; ","")&IF(N(N18)>0,"Dừng ngoài lệnh; ","")&IF(N(J18)>0,"Quá tốc độ; ","")&IF(N(K18)>0,"Lái quá 4h; ","")&IF(N(L18)>0,"Không tắt máy; ","")&IF(OR(P18<>"Đủ",Q18<>"Đủ",R18<>"Đủ"),"Thiếu ảnh; ","")&IF(S18<>"Đạt","Lốp chưa đạt; ","")&IF(N(W18)>'THAM SỐ'!$B$27,"Có mặt quá giờ; ","")&IF(N(X18)>'THAM SỐ'!$B$25,"Lái quá giờ ngày; ","")&IF(ISNUMBER(V18),IF(ABS(V18)>'THAM SỐ'!$B$28,"Lệch km; ",""),""))) | AO18: =IF($A18="","",IF(AM18="Duyệt đủ",AG18,IF(AM18="Duyệt một phần",N(AN18),IF(AM18="Không duyệt",0,"")))) | AP18: =IF(OR($A18="",AO18=""),"",IF(AG18=0,0,ROUND((AC18*'THAM SỐ'!$B$18+AD18*'THAM SỐ'!$B$19+AE18*'THAM SỐ'!$B$20+AF18*'THAM SỐ'!$B$21)*MIN(1,AO18/AG18),0)))
T19: =IF($A19="","",COUNTIFS('LỆNH ĐIỀU XE'!$B$5:$B$604,$A19,'LỆNH ĐIỀU XE'!$C$5:$C$604,$B19)) | U19: =IF($A19="","",SUMIFS('LỆNH ĐIỀU XE'!$J$5:$J$604,'LỆNH ĐIỀU XE'!$B$5:$B$604,$A19,'LỆNH ĐIỀU XE'!$C$5:$C$604,$B19)) | V19: =IF(OR($A19="",D19="",N(U19)=0),"",(D19-U19)/U19) | W19: =IF(OR($A19="",G19="",H19=""),"",ROUND((H19+(H19<G19)-G19)*24,2)) | X19: =IF(OR($A19="",E19=""),"",ROUND(E19*24,2)) | Y19: =IF(OR(W19="",X19=""),"",MAX(0,W19-X19)) | Z19: =IF(OR(W19="",X19="",N(W19)=0),"",X19/W19) | AA19: =IF(OR($A19="",F19="",X19=""),"",MAX(0,ROUND(F19*24-X19,2))) | AB19: =IF(OR($A19="",M19="",N(D19)=0),"",M19/D19*100) | AC19: =IF($A19="","",SUMIFS('CHẶNG TĂNG CA'!$E$5:$E$304,'CHẶNG TĂNG CA'!$A$5:$A$304,$A19,'CHẶNG TĂNG CA'!$B$5:$B$304,$B19)) | AD19: =IF($A19="","",SUMIFS('CHẶNG TĂNG CA'!$F$5:$F$304,'CHẶNG TĂNG CA'!$A$5:$A$304,$A19,'CHẶNG TĂNG CA'!$B$5:$B$304,$B19)) | AE19: =IF($A19="","",SUMIFS('CHẶNG TĂNG CA'!$G$5:$G$304,'CHẶNG TĂNG CA'!$A$5:$A$304,$A19,'CHẶNG TĂNG CA'!$B$5:$B$304,$B19)) | AF19: =IF($A19="","",SUMIFS('CHẶNG TĂNG CA'!$H$5:$H$304,'CHẶNG TĂNG CA'!$A$5:$A$304,$A19,'CHẶNG TĂNG CA'!$B$5:$B$304,$B19)) | AG19: =IF($A19="","",SUM(AC19:AF19)) | AH19: =IF($A19="","",IF(COUNTIFS('LỆNH ĐIỀU XE'!$B$5:$B$604,$A19,'LỆNH ĐIỀU XE'!$C$5:$C$604,$B19,'LỆNH ĐIỀU XE'!$N$5:$N$604,"Có")>0,"Có","Không")) | AI19: =IF(OR($A19="",H19="",N(T19)=0),"",IF(_xlfn.MAXIFS('LỆNH ĐIỀU XE'!$U$5:$U$604,'LỆNH ĐIỀU XE'!$B$5:$B$604,$A19,'LỆNH ĐIỀU XE'!$C$5:$C$604,$B19)=0,"",ROUND((H19+(H19<4/24)-_xlfn.MAXIFS('LỆNH ĐIỀU XE'!$U$5:$U$604,'LỆNH ĐIỀU XE'!$B$5:$B$604,$A19,'LỆNH ĐIỀU XE'!$C$5:$C$604,$B19))*1440,0))) | AJ19: =IF($A19="","",IF(OR(AI19="",V19=""),"Thiếu dữ liệu",IF(AND(AI19<='THAM SỐ'!$B$29,ABS(V19)<='THAM SỐ'!$B$28),"Đạt","Không đạt"))) | AK19: =IF($A19="","",IF(AG19=0,"Không có OT",IF(AND(AH19="Có",AJ19="Đạt"),"Đủ điều kiện","Cần giải trình"))) | AL19: =IF($A19="","",TRIM(IF(T19=0,"Không có lệnh; ","")&IF(N(N19)>0,"Dừng ngoài lệnh; ","")&IF(N(J19)>0,"Quá tốc độ; ","")&IF(N(K19)>0,"Lái quá 4h; ","")&IF(N(L19)>0,"Không tắt máy; ","")&IF(OR(P19<>"Đủ",Q19<>"Đủ",R19<>"Đủ"),"Thiếu ảnh; ","")&IF(S19<>"Đạt","Lốp chưa đạt; ","")&IF(N(W19)>'THAM SỐ'!$B$27,"Có mặt quá giờ; ","")&IF(N(X19)>'THAM SỐ'!$B$25,"Lái quá giờ ngày; ","")&IF(ISNUMBER(V19),IF(ABS(V19)>'THAM SỐ'!$B$28,"Lệch km; ",""),""))) | AO19: =IF($A19="","",IF(AM19="Duyệt đủ",AG19,IF(AM19="Duyệt một phần",N(AN19),IF(AM19="Không duyệt",0,"")))) | AP19: =IF(OR($A19="",AO19=""),"",IF(AG19=0,0,ROUND((AC19*'THAM SỐ'!$B$18+AD19*'THAM SỐ'!$B$19+AE19*'THAM SỐ'!$B$20+AF19*'THAM SỐ'!$B$21)*MIN(1,AO19/AG19),0)))
T20: =IF($A20="","",COUNTIFS('LỆNH ĐIỀU XE'!$B$5:$B$604,$A20,'LỆNH ĐIỀU XE'!$C$5:$C$604,$B20)) | U20: =IF($A20="","",SUMIFS('LỆNH ĐIỀU XE'!$J$5:$J$604,'LỆNH ĐIỀU XE'!$B$5:$B$604,$A20,'LỆNH ĐIỀU XE'!$C$5:$C$604,$B20)) | V20: =IF(OR($A20="",D20="",N(U20)=0),"",(D20-U20)/U20) | W20: =IF(OR($A20="",G20="",H20=""),"",ROUND((H20+(H20<G20)-G20)*24,2)) | X20: =IF(OR($A20="",E20=""),"",ROUND(E20*24,2)) | Y20: =IF(OR(W20="",X20=""),"",MAX(0,W20-X20)) | Z20: =IF(OR(W20="",X20="",N(W20)=0),"",X20/W20) | AA20: =IF(OR($A20="",F20="",X20=""),"",MAX(0,ROUND(F20*24-X20,2))) | AB20: =IF(OR($A20="",M20="",N(D20)=0),"",M20/D20*100) | AC20: =IF($A20="","",SUMIFS('CHẶNG TĂNG CA'!$E$5:$E$304,'CHẶNG TĂNG CA'!$A$5:$A$304,$A20,'CHẶNG TĂNG CA'!$B$5:$B$304,$B20)) | AD20: =IF($A20="","",SUMIFS('CHẶNG TĂNG CA'!$F$5:$F$304,'CHẶNG TĂNG CA'!$A$5:$A$304,$A20,'CHẶNG TĂNG CA'!$B$5:$B$304,$B20)) | AE20: =IF($A20="","",SUMIFS('CHẶNG TĂNG CA'!$G$5:$G$304,'CHẶNG TĂNG CA'!$A$5:$A$304,$A20,'CHẶNG TĂNG CA'!$B$5:$B$304,$B20)) | AF20: =IF($A20="","",SUMIFS('CHẶNG TĂNG CA'!$H$5:$H$304,'CHẶNG TĂNG CA'!$A$5:$A$304,$A20,'CHẶNG TĂNG CA'!$B$5:$B$304,$B20)) | AG20: =IF($A20="","",SUM(AC20:AF20)) | AH20: =IF($A20="","",IF(COUNTIFS('LỆNH ĐIỀU XE'!$B$5:$B$604,$A20,'LỆNH ĐIỀU XE'!$C$5:$C$604,$B20,'LỆNH ĐIỀU XE'!$N$5:$N$604,"Có")>0,"Có","Không")) | AI20: =IF(OR($A20="",H20="",N(T20)=0),"",IF(_xlfn.MAXIFS('LỆNH ĐIỀU XE'!$U$5:$U$604,'LỆNH ĐIỀU XE'!$B$5:$B$604,$A20,'LỆNH ĐIỀU XE'!$C$5:$C$604,$B20)=0,"",ROUND((H20+(H20<4/24)-_xlfn.MAXIFS('LỆNH ĐIỀU XE'!$U$5:$U$604,'LỆNH ĐIỀU XE'!$B$5:$B$604,$A20,'LỆNH ĐIỀU XE'!$C$5:$C$604,$B20))*1440,0))) | AJ20: =IF($A20="","",IF(OR(AI20="",V20=""),"Thiếu dữ liệu",IF(AND(AI20<='THAM SỐ'!$B$29,ABS(V20)<='THAM SỐ'!$B$28),"Đạt","Không đạt"))) | AK20: =IF($A20="","",IF(AG20=0,"Không có OT",IF(AND(AH20="Có",AJ20="Đạt"),"Đủ điều kiện","Cần giải trình"))) | AL20: =IF($A20="","",TRIM(IF(T20=0,"Không có lệnh; ","")&IF(N(N20)>0,"Dừng ngoài lệnh; ","")&IF(N(J20)>0,"Quá tốc độ; ","")&IF(N(K20)>0,"Lái quá 4h; ","")&IF(N(L20)>0,"Không tắt máy; ","")&IF(OR(P20<>"Đủ",Q20<>"Đủ",R20<>"Đủ"),"Thiếu ảnh; ","")&IF(S20<>"Đạt","Lốp chưa đạt; ","")&IF(N(W20)>'THAM SỐ'!$B$27,"Có mặt quá giờ; ","")&IF(N(X20)>'THAM SỐ'!$B$25,"Lái quá giờ ngày; ","")&IF(ISNUMBER(V20),IF(ABS(V20)>'THAM SỐ'!$B$28,"Lệch km; ",""),""))) | AO20: =IF($A20="","",IF(AM20="Duyệt đủ",AG20,IF(AM20="Duyệt một phần",N(AN20),IF(AM20="Không duyệt",0,"")))) | AP20: =IF(OR($A20="",AO20=""),"",IF(AG20=0,0,ROUND((AC20*'THAM SỐ'!$B$18+AD20*'THAM SỐ'!$B$19+AE20*'THAM SỐ'!$B$20+AF20*'THAM SỐ'!$B$21)*MIN(1,AO20/AG20),0)))
